Workbook

Sheet 2025 x 2026
A1: PN | B1: Descrição | C1: 2025 Distri | D1: 2026 Distri | E1: % Alteração
A2: 932AD161100M33 | B2: =_xlfn.XLOOKUP(A2,'2026'!A:A,'2026'!B:B) -> MON LCD PCAP LITE 15.6 VGA/HDMI LOGO CBR BRA | C2: =_xlfn.XLOOKUP(A2,'2025 NOV'!A:A,'2025 NOV'!G:G) -> 247.69393 | D2: =_xlfn.XLOOKUP(A2,'2026'!A:A,'2026'!L:L) -> 259.94688 | E2: =(D2-C2)/C2 -> 0.049468085
A3: 921LD020700733 | B3: =_xlfn.XLOOKUP(A3,'2026'!A:A,'2026'!B:B) -> NPDV FUSION PC 10.1 CX REG 2TPCAP IMP ETH PR DISP.CLI BRA * | C3: =_xlfn.XLOOKUP(A3,'2025 NOV'!A:A,'2025 NOV'!G:G) -> 595.33779 | D3: =_xlfn.XLOOKUP(A3,'2026'!A:A,'2026'!L:L) -> 595.33779 | E3: =(D3-C3)/C3 -> 1.909619e-16
A4: 931FL103300L33 | B4: =_xlfn.XLOOKUP(A4,'2026'!A:A,'2026'!B:B) -> CX REG SIRIUS PC 15.6" PCAP + 15.6" J6412 8/128GB | C4: =_xlfn.XLOOKUP(A4,'2025 NOV'!A:A,'2025 NOV'!G:G) -> #N/A | D4: =_xlfn.XLOOKUP(A4,'2026'!A:A,'2026'!L:L) -> 894.54091 | E4: =(D4-C4)/C4 -> #N/A
A5: 931FL104900L33 | B5: =_xlfn.XLOOKUP(A5,'2026'!A:A,'2026'!B:B) -> CX REG SIRIUS PC 15.6" J6412 8/128GB | C5: =_xlfn.XLOOKUP(A5,'2025 NOV'!A:A,'2025 NOV'!G:G) -> 523.07588 | D5: =_xlfn.XLOOKUP(A5,'2026'!A:A,'2026'!L:L) -> 750.79312 | E5: =(D5-C5)/C5 -> 0.43534267
A6: 921LB660400733 | B6: =_xlfn.XLOOKUP(A6,'2026'!A:A,'2026'!B:B) -> CX REG SIRIUS 15.6" J6412 8+128 GB WIN IOT BRA | C6: =_xlfn.XLOOKUP(A6,'2025 NOV'!A:A,'2025 NOV'!G:G) -> 654.95742 | D6: =_xlfn.XLOOKUP(A6,'2026'!A:A,'2026'!L:L) -> 858.71545 | E6: =(D6-C6)/C6 -> 0.31110117
A7: 931FL105000L33 | B7: =_xlfn.XLOOKUP(A7,'2026'!A:A,'2026'!B:B) -> CX REG SIRIUS PC 15.6" J6412 8/128GB +11.6" NO TOUCH | C7: =_xlfn.XLOOKUP(A7,'2025 NOV'!A:A,'2025 NOV'!G:G) -> 669.93115 | D7: =_xlfn.XLOOKUP(A7,'2026'!A:A,'2026'!L:L) -> 847.30456 | E7: =(D7-C7)/C7 -> 0.26476364
A8: 921LB660600733 | B8: =_xlfn.XLOOKUP(A8,'2026'!A:A,'2026'!B:B) -> CX REG SIRIUS 15.6" + 11.6" J6412 8+128 GB NO TOUCH WIN IOT BRA | C8: =_xlfn.XLOOKUP(A8,'2025 NOV'!A:A,'2025 NOV'!G:G) -> 784.73047 | D8: =_xlfn.XLOOKUP(A8,'2026'!A:A,'2026'!L:L) -> 954.68293 | E8: =(D8-C8)/C8 -> 0.2165743
A9: 931FL105100L33 | B9: =_xlfn.XLOOKUP(A9,'2026'!A:A,'2026'!B:B) -> CX REG SIRIUS PC 15.6" J6412 8/128GB +11.6" TOUCH | C9: =_xlfn.XLOOKUP(A9,'2025 NOV'!A:A,'2025 NOV'!G:G) -> 707.32594 | D9: =_xlfn.XLOOKUP(A9,'2026'!A:A,'2026'!L:L) -> 887.95624 | E9: =(D9-C9)/C9 -> 0.25537067
A10: 921LB660800733 | B10: =_xlfn.XLOOKUP(A10,'2026'!A:A,'2026'!B:B) -> CX REG SIRIUS 15.6" + 11.6" PCAP J6412 8+128 GB TOUCH WIN IOT BRA | C10: =_xlfn.XLOOKUP(A10,'2025 NOV'!A:A,'2025 NOV'!G:G) -> 822.83558 | D10: =_xlfn.XLOOKUP(A10,'2026'!A:A,'2026'!L:L) -> 995.81301 | E10: =(D10-C10)/C10 -> 0.21022114
A11: 931FL102900L33 | B11: =_xlfn.XLOOKUP(A11,'2026'!A:A,'2026'!B:B) -> CX REG VEGA 11.6 J6412 8+128 GB | C11: =_xlfn.XLOOKUP(A11,'2025 NOV'!A:A,'2025 NOV'!G:G) -> 647.89307 | D11: =_xlfn.XLOOKUP(A11,'2026'!A:A,'2026'!L:L) -> 827.446 | E11: =(D11-C11)/C11 -> 0.27713359
A12: 931FL106000L33 | B12: =_xlfn.XLOOKUP(A12,'2026'!A:A,'2026'!B:B) -> CX REG VEGA PC 11.6" J6412 4/128GB IMP TER 80MM + ALTO-FALANTE | C12: =_xlfn.XLOOKUP(A12,'2025 NOV'!A:A,'2025 NOV'!G:G) -> 647.96296 | D12: =_xlfn.XLOOKUP(A12,'2026'!A:A,'2026'!L:L) -> 827.446 | E12: =(D12-C12)/C12 -> 0.27699583
A13: 921LB660100733 | B13: =_xlfn.XLOOKUP(A13,'2026'!A:A,'2026'!B:B) -> CX REG VEGA 11.6 J6412 4+128 GB WIN IOT BRA | C13: =_xlfn.XLOOKUP(A13,'2025 NOV'!A:A,'2025 NOV'!G:G) -> 843.49486 | D13: =_xlfn.XLOOKUP(A13,'2026'!A:A,'2026'!L:L) -> 934.65262 | E13: =(D13-C13)/C13 -> 0.10807151
... A15: 921LB660200733 | B15: =_xlfn.XLOOKUP(A15,'2026'!A:A,'2026'!B:B) -> CX REG ANTARES 15.6 J6412 4+128 GB WIN IOT BRA | C15: =_xlfn.XLOOKUP(A15,'2025 NOV'!A:A,'2025 NOV'!G:G) -> 810.50503 | D15: =_xlfn.XLOOKUP(A15,'2026'!A:A,'2026'!L:L) -> 1067.4078 | E15: =(D15-C15)/C15 -> 0.31696632
A16: 921LB662500733 | B16: =_xlfn.XLOOKUP(A16,'2025 NOV'!A:A,'2025 NOV'!B:B) -> CX REG SIRIUS PC 15.6" I3-12TH 8/128GB BRA + 11.6 NO TOUCH | C16: =_xlfn.XLOOKUP(A16,'2025 NOV'!A:A,'2025 NOV'!G:G) -> 960.78631 | D16: =_xlfn.XLOOKUP(A16,'2026'!A:A,'2026'!L:L) -> #N/A | E16: =(D16-C16)/C16 -> #N/A
A17: 921LB661100733 | B17: =_xlfn.XLOOKUP(A17,'2026'!A:A,'2026'!B:B) -> CX REG SIRIUS PC 15.6" + 11.6" PCAP I3 10TH 8/128GB | C17: =_xlfn.XLOOKUP(A17,'2025 NOV'!A:A,'2025 NOV'!G:G) -> 1001.2584 | D17: =_xlfn.XLOOKUP(A17,'2026'!A:A,'2026'!L:L) -> 788.66242 | E17: =(D17-C17)/C17 -> -0.21232877
A18: 931FL104600L33 | B18: =_xlfn.XLOOKUP(A18,'2026'!A:A,'2026'!B:B) -> CX REG VEGA PC 11.6" I3-12TH 8/128GB IMP TER 80MM BRA | C18: =_xlfn.XLOOKUP(A18,'2025 NOV'!A:A,'2025 NOV'!G:G) -> #N/A | D18: =_xlfn.XLOOKUP(A18,'2026'!A:A,'2026'!L:L) -> 1030.2253 | E18: =(D18-C18)/C18 -> #N/A
A19: 921LB661200733 | B19: =_xlfn.XLOOKUP(A19,'2026'!A:A,'2026'!B:B) -> CX REG VEGA 11.6 I3 10TH 8+128GB WIN PRO BRA (47 pç) | C19: =_xlfn.XLOOKUP(A19,'2025 NOV'!A:A,'2025 NOV'!G:G) -> 1051.5578 | D19: =_xlfn.XLOOKUP(A19,'2026'!A:A,'2026'!L:L) -> 1044.3072 | E19: =(D19-C19)/C19 -> -0.006895175
A20: 921LB662300733 | B20: =_xlfn.XLOOKUP(A20,'2026'!A:A,'2026'!B:B) -> CX REG SIRIUS PC 15.6" I5 12TH + 11.6 PCAP + WIFI | C20: =_xlfn.XLOOKUP(A20,'2025 NOV'!A:A,'2025 NOV'!G:G) -> 1147.502 | D20: =_xlfn.XLOOKUP(A20,'2026'!A:A,'2026'!L:L) -> 1207.8513 | E20: =(D20-C20)/C20 -> 0.052591928
A21: 935FL103400L33 | B21: =_xlfn.XLOOKUP(A21,'2026'!A:A,'2026'!B:B) -> CX REG SIRIUS PC 15.6" I5 12TH 8/256GB | C21: =_xlfn.XLOOKUP(A21,'2025 NOV'!A:A,'2025 NOV'!G:G) -> 918.83631 | D21: =_xlfn.XLOOKUP(A21,'2026'!A:A,'2026'!L:L) -> 1061.1988 | E21: =(D21-C21)/C21 -> 0.15493781
A22: 921LB662400733 | B22: =_xlfn.XLOOKUP(A22,'2026'!A:A,'2026'!B:B) -> CX REG SIRIUS PC 15.6" I5-12TH 8/256GB +11.6" NO TOUCH | C22: =_xlfn.XLOOKUP(A22,'2025 NOV'!A:A,'2025 NOV'!G:G) -> 1052.2037 | D22: =_xlfn.XLOOKUP(A22,'2026'!A:A,'2026'!L:L) -> 1157.7136 | E22: =(D22-C22)/C22 -> 0.10027512
A23: 921LB662200733 | B23: =_xlfn.XLOOKUP(A23,'2026'!A:A,'2026'!B:B) -> CX REG SIRIUS PC 15.6" I5 -12TH 8/256GB +11.6" TOUCH | C23: =_xlfn.XLOOKUP(A23,'2025 NOV'!A:A,'2025 NOV'!G:G) -> 1092.1074 | D23: =_xlfn.XLOOKUP(A23,'2026'!A:A,'2026'!L:L) -> 1198.3012 | E23: =(D23-C23)/C23 -> 0.097237544
A24: 921LB660100L33 | B24: =_xlfn.XLOOKUP(A24,'2026'!A:A,'2026'!B:B) -> CX REG SIRIUS 15.6 PCAP I5 7USB WIFI+BT BRA | C24: =_xlfn.XLOOKUP(A24,'2025 NOV'!A:A,'2025 NOV'!G:G) -> 916.57314 | D24: =_xlfn.XLOOKUP(A24,'2026'!A:A,'2026'!L:L) -> 1067.4472 | E24: =(D24-C24)/C24 -> 0.16460663
A25: 921LB662000733 | B25: =_xlfn.XLOOKUP(A25,'2026'!A:A,'2026'!B:B) -> CX REG SIRIUS 15.6"+15.6" PCAP I5 12TH 8/256 WIFI | C25: =_xlfn.XLOOKUP(A25,'2025 NOV'!A:A,'2025 NOV'!G:G) -> 1069.9588 | D25: =_xlfn.XLOOKUP(A25,'2026'!A:A,'2026'!L:L) -> 1220.7977 | E25: =(D25-C25)/C25 -> 0.14097633
A26: 935KY432500L33 | B26: =_xlfn.XLOOKUP(A26,'2026'!A:A,'2026'!B:B) -> SIRIUS AND - RK3568 2GB/16GB 15.6" PCAP | C26: =_xlfn.XLOOKUP(A26,'2025 NOV'!A:A,'2025 NOV'!G:G) -> 456.07591 | D26: =_xlfn.XLOOKUP(A26,'2026'!A:A,'2026'!L:L) -> 549.04474 | E26: =(D26-C26)/C26 -> 0.20384508
A27: 921LB662100733 | B27: =_xlfn.XLOOKUP(A27,'2026'!A:A,'2026'!B:B) -> CX REG SIRIUS AND 15.6" + 11.6" 2/16GB | C27: =_xlfn.XLOOKUP(A27,'2025 NOV'!A:A,'2025 NOV'!G:G) -> #N/A | D27: =_xlfn.XLOOKUP(A27,'2026'!A:A,'2026'!L:L) -> 654.28721 | E27: =(D27-C27)/C27 -> #N/A
A28: 935KY432400L33 | B28: =_xlfn.XLOOKUP(A28,'2026'!A:A,'2026'!B:B) -> CX REG VEGA AND 11 11.6" RK3568 4/16 GB IMP TER 80MM | C28: =_xlfn.XLOOKUP(A28,'2025 NOV'!A:A,'2025 NOV'!G:G) -> 923.71527 | D28: =_xlfn.XLOOKUP(A28,'2026'!A:A,'2026'!L:L) -> 638.86179 | E28: =(D28-C28)/C28 -> -0.30837801
... A56: 915NB020200333 | B56: =_xlfn.XLOOKUP(A56,'2026'!A:A,'2026'!B:B) -> IMP TERM PM2 MINI 4.7-5V C KIT CABOS RS232 BRA | C56: =_xlfn.XLOOKUP(A56,'2025 NOV'!A:A,'2025 NOV'!G:G) -> 114.43269 | D56: =_xlfn.XLOOKUP(A56,'2026'!A:A,'2026'!L:L) -> 114.43269 | E56: =(D56-C56)/C56 -> -2.4837055e-16
A57: 915GJ010100322 | B57: =_xlfn.XLOOKUP(A57,'2025 NOV'!A:A,'2025 NOV'!B:B) -> IMP TERM PLUS4 KIT CABOS RS232 BRA | C57: =_xlfn.XLOOKUP(A57,'2025 NOV'!A:A,'2025 NOV'!G:G) -> 342.46763 | D57: =_xlfn.XLOOKUP(A57,'2026'!A:A,'2026'!L:L) -> #N/A | E57: =(D57-C57)/C57 -> #N/A
A58: 9C3FH010000002 | B58: =_xlfn.XLOOKUP(A58,'2026'!A:A,'2026'!B:B) -> LEITOR COD BARRAS 2D USB KBR2D-C CASE | C58: =_xlfn.XLOOKUP(A58,'2025 NOV'!A:A,'2025 NOV'!G:G) -> 65.41887 | D58: =_xlfn.XLOOKUP(A58,'2026'!A:A,'2026'!L:L) -> 65.41887 | E58: =(D58-C58)/C58 -> 0
A59: 9C1FH016800010 | B59: =_xlfn.XLOOKUP(A59,'2026'!A:A,'2026'!B:B) -> LEITOR COD BARRAS 2D USB CBR2D-C CASE | C59: =_xlfn.XLOOKUP(A59,'2025 NOV'!A:A,'2025 NOV'!G:G) -> 45.765073 | D59: =_xlfn.XLOOKUP(A59,'2026'!A:A,'2026'!L:L) -> 45.765073 | E59: =(D59-C59)/C59 -> 3.1051747e-16
A60: 9C1FH016800020 | B60: =_xlfn.XLOOKUP(A60,'2026'!A:A,'2026'!B:B) -> LEITOR DE CODIGO DE BARRAS CBR2D-C USB/SERIAL | C60: =_xlfn.XLOOKUP(A60,'2025 NOV'!A:A,'2025 NOV'!G:G) -> 59.397222 | D60: =_xlfn.XLOOKUP(A60,'2026'!A:A,'2026'!L:L) -> 59.397222 | E60: =(D60-C60)/C60 -> -1.1962558e-16
A61: 26500000000165 | B61: =_xlfn.XLOOKUP(A61,'2026'!A:A,'2026'!B:B) -> CABO SERIAL DB9/RJ45 PARA LEITOR CBR2D-C 2M | C61: =_xlfn.XLOOKUP(A61,'2025 NOV'!A:A,'2025 NOV'!G:G) -> 8.4345953 | D61: =_xlfn.XLOOKUP(A61,'2026'!A:A,'2026'!L:L) -> 8.4345953 | E61: =(D61-C61)/C61 -> 3.5802626e-15
A62: 992ED040600233 | B62: =_xlfn.XLOOKUP(A62,'2026'!A:A,'2026'!B:B) -> LEITOR DE CODIGO DE BARRAS CBR2D-T USB | C62: =_xlfn.XLOOKUP(A62,'2025 NOV'!A:A,'2025 NOV'!G:G) -> 120.74189 | D62: =_xlfn.XLOOKUP(A62,'2026'!A:A,'2026'!L:L) -> 120.74189 | E62: =(D62-C62)/C62 -> 8.2387297e-16
A63: 26500000000172 | B63: =_xlfn.XLOOKUP(A63,'2026'!A:A,'2026'!B:B) -> CABO SERIAL DB9/RJ45 PARA LEITOR CBR2D-T 2M | C63: =_xlfn.XLOOKUP(A63,'2025 NOV'!A:A,'2025 NOV'!G:G) -> 7.7011522 | D63: =_xlfn.XLOOKUP(A63,'2026'!A:A,'2026'!L:L) -> 7.7011522 | E63: =(D63-C63)/C63 -> -3.4599177e-16
A64: 976ZZ010000347 | B64: =_xlfn.XLOOKUP(A64,'2026'!A:A,'2026'!B:B) -> CABO SERIAL DB9/RJ45 PARA LEITOR CBR2D-V 2M | C64: =_xlfn.XLOOKUP(A64,'2025 NOV'!A:A,'2025 NOV'!G:G) -> #N/A | D64: =_xlfn.XLOOKUP(A64,'2026'!A:A,'2026'!L:L) -> 8.4538085 | E64: =(D64-C64)/C64 -> #N/A
A65: 932AD180100M33 | B65: =_xlfn.XLOOKUP(A65,'2026'!A:A,'2026'!B:B) -> CTM-0700 OF MONITOR DE VIDEO 7" COM TOUCH PCAP | C65: =_xlfn.XLOOKUP(A65,'2025 NOV'!A:A,'2025 NOV'!G:G) -> 186.29011 | D65: =_xlfn.XLOOKUP(A65,'2026'!A:A,'2026'!L:L) -> 186.29011 | E65: =(D65-C65)/C65 -> -3.0513385e-16
A66: 932AD180200M33 | B66: =_xlfn.XLOOKUP(A66,'2026'!A:A,'2026'!B:B) -> CTM-0700 OF MONITOR DE VIDEO 7" NO TOUCH PCAP | C66: =_xlfn.XLOOKUP(A66,'2025 NOV'!A:A,'2025 NOV'!G:G) -> 129.4895 | D66: =_xlfn.XLOOKUP(A66,'2026'!A:A,'2026'!L:L) -> 129.4895 | E66: =(D66-C66)/C66 -> -2.414395e-15
A67: 932AD150100M33 | B67: =_xlfn.XLOOKUP(A67,'2026'!A:A,'2026'!B:B) -> CTM-1010 OF MONITOR DE VIDEO 10.1" COM TOUCH PCAP | C67: =_xlfn.XLOOKUP(A67,'2025 NOV'!A:A,'2025 NOV'!G:G) -> 187.91 | D67: =_xlfn.XLOOKUP(A67,'2026'!A:A,'2026'!L:L) -> 187.906 | E67: =(D67-C67)/C67 -> -2.1308143e-05
A68: 932AD150900M33 | B68: =_xlfn.XLOOKUP(A68,'2026'!A:A,'2026'!B:B) -> CTM-1010 OF MONITOR DE VIDEO 10.1" NO TOUCH | C68: =_xlfn.XLOOKUP(A68,'2025 NOV'!A:A,'2025 NOV'!G:G) -> 146.94 | D68: =_xlfn.XLOOKUP(A68,'2026'!A:A,'2026'!L:L) -> 146.94379 | E68: =(D68-C68)/C68 -> 2.5787731e-05
...

Sheet 2026 - Mar - V2
A1: PN | B1: DESCRIÇÃO | C1: NCM | D1: PPB | E1: GARANTIA | F1: IPI | G1: ICMS | H1: ESTADO DESTINO | I1: NATUREZA OPERAÇÃO | J1: IE? | K1: IMPOSTO | L1: DISTRI | M1: 1 - 5 | N1: 6 - 10 | O1: 10+ | P1: ESPECIAL | Q1: SHOWROOM | R1: Tem na 2025? | S1: Categoria | T1: Processador | U1: Tela Principal | V1: Tela Secundária | W1: Touch 2a Tela | X1: RAM | Y1: SSD
A2: 932AD161100M33 | B2: MON LCD PCAP LITE 15.6" VGA/HDMI LOGO CBR COM PEDESTAL BRA | C2: 8528.52.00 | D2: Não | E2: 1 ano | F2: 0.15 | G2: =IF(D2="Sim",0.12,0.04) -> 0.04 | L2: 259.94688 | M2: =L2*1.23 -> 319.73466 | N2: =L2*1.2 -> 311.93625 | O2: =L2*1.17 -> 304.13785 | P2: =(O2+L2)/2 -> 282.04236 | Q2: =L2*1.01249086924762 -> 263.19384 | S2: MONITOR LITE | T2: N/A | U2: 15.6 | V2: N/A | W2: N/A | X2: N/A | Y2: N/A
A3: 931FL104900L33 | B3: CX REG SIRIUS PC 15.6" J6412 8/128GB | C3: 8470.50.10 | D3: Não | E3: 3 anos | F3: 0.15 | G3: =IF(D3="Sim",0.12,0.04) -> 0.04 | L3: 750.79312 | M3: =L3*1.23 -> 923.47554 | N3: =L3*1.2 -> 900.95175 | O3: =L3*1.17 -> 878.42795 | P3: =(O3+L3)/2 -> 814.61054 | Q3: =L3*1.01249086924762 -> 760.17118 | S3: PDV | T3: J6412 | U3: 15.6 | V3: N/A | W3: N/A | X3: 8 | Y3: 128
A4: 931FL105000L33 | B4: CX REG SIRIUS PC 15.6"+11.6" J6412 8/128GB | C4: 8470.50.10 | D4: Não | E4: 3 anos | F4: 0.15 | G4: =IF(D4="Sim",0.12,0.04) -> 0.04 | L4: 847.30456 | M4: =L4*1.23 -> 1042.1846 | N4: =L4*1.2 -> 1016.7655 | O4: =L4*1.17 -> 991.34633 | P4: =(O4+L4)/2 -> 919.32544 | Q4: =L4*1.01249086924762 -> 857.88813 | S4: PDV | T4: J6412 | U4: 15.6 | V4: 11.6 | W4: NÃO | X4: 8 | Y4: 128
A5: 931FL105100L33 | B5: CX REG SIRIUS PC 15.6"+11.6" PCAP J6412 8/128GB | C5: 8470.50.10 | D5: Não | E5: 3 anos | F5: 0.15 | G5: =IF(D5="Sim",0.12,0.04) -> 0.04 | L5: 887.95624 | M5: =L5*1.23 -> 1092.1862 | N5: =L5*1.2 -> 1065.5475 | O5: =L5*1.17 -> 1038.9088 | P5: =(O5+L5)/2 -> 963.43252 | Q5: =L5*1.01249086924762 -> 899.04758 | S5: PDV | T5: J6412 | U5: 15.6 | V5: 11.6 | W5: SIM | X5: 8 | Y5: 128
A6: 931FL102900L33 | B6: CX REG VEGA PC 11.6" J6412 4/128GB IMP TER 80MM | C6: 8470.50.10 | D6: Não | E6: 3 anos | F6: 0.15 | G6: =IF(D6="Sim",0.12,0.04) -> 0.04 | L6: 827.446 | M6: =L6*1.23 -> 1017.7586 | N6: =L6*1.2 -> 992.9352 | O6: =L6*1.17 -> 968.11182 | P6: =(O6+L6)/2 -> 897.77891 | Q6: =L6*1.01249086924762 -> 837.78152 | S6: PDV | T6: J6412 | U6: 15.6 | V6: N/A | W6: N/A | X6: 8 | Y6: 128
A7: 931FL106000L33 | B7: CX REG VEGA PC 11.6" J6412 4/128GB IMP TER 80MM + ALTO-FALANTE | C7: 8470.50.10 | D7: Não | E7: 3 anos | F7: 0.15 | G7: =IF(D7="Sim",0.12,0.04) -> 0.04 | L7: 827.446 | M7: =L7*1.23 -> 1017.7586 | N7: =L7*1.2 -> 992.9352 | O7: =L7*1.17 -> 968.11182 | P7: =(O7+L7)/2 -> 897.77891 | Q7: =L7*1.01249086924762 -> 837.78152 | S7: PDV | T7: J6412 | U7: 15.6 | V7: N/A | W7: N/A | X7: 4 | Y7: 128
A8: 931FL103000L33 | B8: CX REG ANTARES PC 15.6"+11.6" J6412 4/128GB IMP TER 80MM | C8: 8470.50.10 | D8: Não | E8: 3 anos | F8: 0.15 | G8: =IF(D8="Sim",0.12,0.04) -> 0.04 | L8: 706.87405 | M8: =L8*1.23 -> 869.45508 | N8: =L8*1.2 -> 848.24886 | O8: =L8*1.17 -> 827.04264 | P8: =(O8+L8)/2 -> 766.95835 | Q8: =L8*1.01249086924762 -> 715.70352 | S8: PDV | T8: J6412 | U8: 15.6 | V8: 11.6 | W8: SIM | X8: 4 | Y8: 128
A9: 931FL103000L33 | B9: CX REG ANTARES PC 15.6"+11.6" J6412 8/128GB IMP TER 80MM | C9: 8470.50.10 | D9: Não | E9: 3 anos | F9: 0.15 | G9: =IF(D9="Sim",0.12,0.04) -> 0.04 | L9: 955.67064 | M9: =L9*1.23 -> 1175.4749 | N9: =L9*1.2 -> 1146.8048 | O9: =L9*1.17 -> 1118.1346 | P9: =(O9+L9)/2 -> 1036.9026 | Q9: =L9*1.01249086924762 -> 967.60779 | S9: PDV | T9: J6412 | U9: 15.6 | V9: 11.6 | W9: SIM | X9: 4 | Y9: 128
A10: 931FL104600L33 | B10: CX REG VEGA PC 11.6" I3-10TH 8/128GB IMP TER 80MM BRA | C10: 8470.50.10 | D10: Não | E10: 3 anos | F10: 0.15 | G10: =IF(D10="Sim",0.12,0.04) -> 0.04 | L10: 1030.2253 | M10: =L10*1.23 -> 1267.1771 | N10: =L10*1.2 -> 1236.2703 | O10: =L10*1.17 -> 1205.3636 | P10: =(O10+L10)/2 -> 1117.7944 | Q10: =L10*1.01249086924762 -> 1043.0937 | S10: PDV | T10: I3 | U10: 15.6 | V10: N/A | W10: N/A | X10: 8 | Y10: 128
A11: 08GB S/ PEDESTAL | B11: CX REG SIRIUS 15.6 PCAP I5 12TH 8/256GB WIFI - SEM PEDESTAL | C11: 8470.50.10 | D11: Não | E11: 3 anos | F11: 0.15 | G11: =IF(D11="Sim",0.12,0.04) -> 0.04 | L11: 1040.3038 | M11: =L11*1.23 -> 1279.5736 | N11: =L11*1.2 -> 1248.3645 | O11: =L11*1.17 -> 1217.1554 | P11: =(O11+L11)/2 -> 1128.7296 | Q11: =L11*1.01249086924762 -> 1053.2981 | S11: PDV | T11: I5 | U11: 15.6 | V11: N/A | W11: N/A | X11: 8 | Y11: 256
A12: 935FL103400L33 | B12: CX REG SIRIUS PC 15.6" I5 12TH 8/256GB | C12: 8470.50.10 | D12: Não | E12: 3 anos | F12: 0.15 | G12: =IF(D12="Sim",0.12,0.04) -> 0.04 | L12: 1061.1988 | M12: =L12*1.23 -> 1305.2745 | N12: =L12*1.2 -> 1273.4386 | O12: =L12*1.17 -> 1241.6026 | P12: =(O12+L12)/2 -> 1151.4007 | Q12: =L12*1.01249086924762 -> 1074.4541 | S12: PDV | T12: I5 | U12: 15.6 | V12: N/A | W12: N/A | X12: 8 | Y12: 256
A13: 921LB660100L33 | B13: CX REG SIRIUS 15.6" PCAP WIFI+BT BRA I5 | C13: 8470.50.10 | D13: Não | E13: 3 anos | F13: 0.15 | G13: =IF(D13="Sim",0.12,0.04) -> 0.04 | L13: 1067.4472 | M13: =L13*1.23 -> 1312.96 | N13: =L13*1.2 -> 1280.9366 | O13: =L13*1.17 -> 1248.9132 | P13: =(O13+L13)/2 -> 1158.1802 | Q13: =L13*1.01249086924762 -> 1080.7805 | S13: PDV | T13: I5 | U13: 15.6 | V13: N/A | W13: N/A | X13: 8 | Y13: 256
A14: 921LB662400733 | B14: CX REG SIRIUS PC 15.6" I5-12TH 8/256GB +11.6" NO TOUCH | C14: 8470.50.10 | D14: Não | E14: 3 anos | F14: 0.15 | G14: =IF(D14="Sim",0.12,0.04) -> 0.04 | L14: 1157.7136 | M14: =L14*1.23 -> 1423.9877 | N14: =L14*1.2 -> 1389.2563 | O14: =L14*1.17 -> 1354.5249 | P14: =(O14+L14)/2 -> 1256.1192 | Q14: =L14*1.01249086924762 -> 1172.1744 | S14: PDV | T14: I5 | U14: 15.6 | V14: 11.6 | W14: NÃO | X14: 8 | Y14: 256
A15: 921LB662200733 | B15: CX REG SIRIUS PC 15.6"+11.6" PCAP I5 12TH 8/256GB | C15: 8470.50.10 | D15: Não | E15: 3 anos | F15: 0.15 | G15: =IF(D15="Sim",0.12,0.04) -> 0.04 | L15: 1198.3012 | M15: =L15*1.23 -> 1473.9105 | N15: =L15*1.2 -> 1437.9615 | O15: =L15*1.17 -> 1402.0125 | P15: =(O15+L15)/2 -> 1300.1569 | Q15: =L15*1.01249086924762 -> 1213.2691 | S15: PDV | T15: I5 | U15: 15.6 | V15: 11.6 | W15: SIM | X15: 8 | Y15: 256
A16: 921LB662300733 | B16: CX REG SIRIUS PC 15.6"+11.6" PCAP I5 12TH 8/256GB+WIFI | C16: 8470.50.10 | D16: Não | E16: 3 anos | F16: 0.15 | G16: =IF(D16="Sim",0.12,0.04) -> 0.04 | L16: 1207.8513 | M16: =L16*1.23 -> 1485.6571 | N16: =L16*1.2 -> 1449.4216 | O16: =L16*1.17 -> 1413.186 | P16: =(O16+L16)/2 -> 1310.5187 | Q16: =L16*1.01249086924762 -> 1222.9384 | S16: PDV | T16: I5 | U16: 15.6 | V16: 11.6 | W16: SIM | X16: 8 | Y16: 256
A17: 935KY432500L33 | B17: CX REG SIRIUS AND 11 15.6" RK3568 2/32 GB | C17: 8470.50.10 | D17: Não | E17: 3 anos | F17: 0.15 | G17: =IF(D17="Sim",0.12,0.04) -> 0.04 | L17: 549.04474 | M17: =L17*1.23 -> 675.32503 | N17: =L17*1.2 -> 658.85369 | O17: =L17*1.17 -> 642.38235 | P17: =(O17+L17)/2 -> 595.71355 | Q17: =L17*1.01249086924762 -> 555.90279 | S17: PDV | T17: ANDROID | U17: 15.6 | V17: N/A | W17: N/A | X17: 2 | Y17: 16
A18: 921LB662100733 | B18: CX REG SIRIUS AND 15.6"+11.6" S/TOUCH 2/32GB BRA | C18: 8470.50.10 | D18: Não | E18: 3 anos | F18: 0.15 | G18: =IF(D18="Sim",0.12,0.04) -> 0.04 | L18: 654.28721 | M18: =L18*1.23 -> 804.77326 | N18: =L18*1.2 -> 785.14465 | O18: =L18*1.17 -> 765.51603 | P18: =(O18+L18)/2 -> 709.90162 | Q18: =L18*1.01249086924762 -> 662.45982 | S18: PDV | T18: ANDROID | U18: 15.6 | V18: 11.6 | W18: NÃO | X18: 2 | Y18: 16
A19: 921LB662700733 | B19: CX REG SIRIUS AND 15.6"+11.6" PCAP 2/32 GB BRA | C19: 8470.50.10 | D19: Não | E19: 3 anos | F19: 0.15 | G19: =IF(D19="Sim",0.12,0.04) -> 0.04 | L19: 694.97476 | M19: =L19*1.23 -> 854.81896 | N19: =L19*1.2 -> 833.96972 | O19: =L19*1.17 -> 813.12047 | P19: =(O19+L19)/2 -> 754.04762 | Q19: =L19*1.01249086924762 -> 703.6556 | S19: PDV | T19: ANDROID | U19: 15.6 | V19: 11.6 | W19: SIM | X19: 2 | Y19: 32
A20: 935KY432400L33 | B20: CX REG VEGA AND 11 11.6" RK3568 2/32GB IMP TER 80MM | C20: 8470.50.10 | D20: Não | E20: 3 anos | F20: 0.15 | G20: =IF(D20="Sim",0.12,0.04) -> 0.04 | L20: 638.86179 | M20: =L20*1.23 -> 785.8 | N20: =L20*1.2 -> 766.63415 | O20: =L20*1.17 -> 747.46829 | P20: =(O20+L20)/2 -> 693.16504 | Q20: =L20*1.01249086924762 -> 646.84173 | S20: PDV | T20: ANDROID | U20: 15.6 | V20: N/A | W20: N/A | X20: 4 | Y20: 16
A21: 931FL103100L33 | B21: CX REG ANTARES AND 11 15.6"+11.6" RK3568 2/32GB IMP TER 80MM (8pç) | C21: 8470.50.10 | D21: Não | E21: 3 anos | F21: 0.15 | G21: =IF(D21="Sim",0.12,0.04) -> 0.04 | L21: 669.01808 | M21: =L21*1.23 -> 822.89224 | N21: =L21*1.2 -> 802.8217 | O21: =L21*1.17 -> 782.75116 | P21: =(O21+L21)/2 -> 725.88462 | Q21: =L21*1.01249086924762 -> 677.3747 | S21: PDV | T21: ANDROID | U21: 15.6 | V21: 11.6 | W21: SIM | X21: 2 | Y21: 32
A22: 931FL103100L33 | B22: CX REG ANTARES AND 11 15.6"+11.6" RK3568 4/32GB IMP TER 80MM | C22: 8470.50.10 | D22: Não | E22: 3 anos | F22: 0.15 | G22: =IF(D22="Sim",0.12,0.04) -> 0.04 | L22: 790.02439 | M22: =L22*1.23 -> 971.73 | N22: =L22*1.2 -> 948.02927 | O22: =L22*1.17 -> 924.32854 | P22: =(O22+L22)/2 -> 857.17646 | Q22: =L22*1.01249086924762 -> 799.89248 | S22: PDV | T22: ANDROID | U22: 15.6 | V22: 11.6 | W22: SIM | X22: 2 | Y22: 32
A23: 921LB662600733 | B23: CX REG SIRIUS PC 15.6" 8XUSB N97 8/128GB | C23: 8470.50.10 | D23: Não | E23: 3 anos | F23: 0.15 | G23: =IF(D23="Sim",0.12,0.04) -> 0.04 | L23: 894.07632 | M23: =L23*1.23 -> 1099.7139 | N23: =L23*1.2 -> 1072.8916 | O23: =L23*1.17 -> 1046.0693 | P23: =(O23+L23)/2 -> 970.0728 | Q23: =L23*1.01249086924762 -> 905.24411 | S23: PDV | T23: N97 | U23: 15.6 | V23: N/A | W23: N/A | X23: 8 | Y23: 128
A24: 935RE010100L33 | B24: ORION 21.5" AIO-2150 J6412 8/128GB BRA | C24: 8471.49.00 | D24: Não | E24: 1 ano | F24: 0.15 | G24: =IF(D24="Sim",0.12,0.04) -> 0.04 | L24: 826.78638 | M24: =L24*1.23 -> 1016.9473 | N24: =L24*1.2 -> 992.14366 | O24: =L24*1.17 -> 967.34007 | P24: =(O24+L24)/2 -> 897.06322 | Q24: =L24*1.01249086924762 -> 837.11366 | S24: PDV | T24: J6412 | U24: 21.5 | V24: N/A | W24: N/A | X24: 8 | Y24: 128
A25: 935RE010200L33 | B25: ORION 23.8" AIO-2380 J6412 8/128GB BRA | C25: 8471.49.00 | D25: Não | E25: 1 ano | F25: 0.15 | G25: =IF(D25="Sim",0.12,0.04) -> 0.04 | L25: 890.04523 | M25: =L25*1.23 -> 1094.7556 | N25: =L25*1.2 -> 1068.0543 | O25: =L25*1.17 -> 1041.3529 | P25: =(O25+L25)/2 -> 965.69908 | Q25: =L25*1.01249086924762 -> 901.16267 | S25: PDV | T25: J6412 | U25: 23.8 | V25: N/A | W25: N/A | X25: 8 | Y25: 128
A26: 935RE010300L33 | B26: ORION 27" AIO-2700 J6412 8/128GB BRA | C26: 8471.49.00 | D26: Não | E26: 1 ano | F26: 0.15 | G26: =IF(D26="Sim",0.12,0.04) -> 0.04 | L26: 923.37517 | M26: =L26*1.23 -> 1135.7515 | N26: =L26*1.2 -> 1108.0502 | O26: =L26*1.17 -> 1080.3489 | P26: =(O26+L26)/2 -> 1001.8621 | Q26: =L26*1.01249086924762 -> 934.90892 | S26: PDV | T26: J6412 | U26: 27 | V26: N/A | W26: N/A | X26: 8 | Y26: 128
A27: 935RE010400L33 | B27: ORION 21.5" AIO-2150 I5 12TH 8/128GB BRA | C27: 8471.49.00 | D27: Não | E27: 1 ano | F27: 0.15 | G27: =IF(D27="Sim",0.12,0.04) -> 0.04 | L27: 1135.9385 | M27: =L27*1.23 -> 1397.2044 | N27: =L27*1.2 -> 1363.1262 | O27: =L27*1.17 -> 1329.0481 | P27: =(O27+L27)/2 -> 1232.4933 | Q27: =L27*1.01249086924762 -> 1150.1274 | S27: PDV | T27: I5 | U27: 21.5 | V27: N/A | W27: N/A | X27: 8 | Y27: 128
A28: 935RE010500L33 | B28: ORION 23.8" AIO-2380 I5 12TH 8/128GB BRA | C28: 8471.49.00 | D28: Não | E28: 1 ano | F28: 0.15 | G28: =IF(D28="Sim",0.12,0.04) -> 0.04 | L28: 1197.837 | M28: =L28*1.23 -> 1473.3395 | N28: =L28*1.2 -> 1437.4043 | O28: =L28*1.17 -> 1401.4692 | P28: =(O28+L28)/2 -> 1299.6531 | Q28: =L28*1.01249086924762 -> 1212.799 | S28: PDV | T28: I5 | U28: 23.8 | V28: N/A | W28: N/A | X28: 8 | Y28: 128
A29: 935RE010600L33 | B29: ORION 27" AIO-2700 I5 12TH 8/128GB BRA | C29: 8471.49.00 | D29: Não | E29: 1 ano | F29: 0.15 | G29: =IF(D29="Sim",0.12,0.04) -> 0.04 | L29: 1233.2075 | M29: =L29*1.23 -> 1516.8452 | N29: =L29*1.2 -> 1479.849 | O29: =L29*1.17 -> 1442.8528 | P29: =(O29+L29)/2 -> 1338.0301 | Q29: =L29*1.01249086924762 -> 1248.6113 | S29: PDV | T29: I5 | U29: 27 | V29: N/A | W29: N/A | X29: 8 | Y29: 128
B30: LICENÇA WIN IOT X PCPOS (CELERON) | C30: #N/A | G30: =IF(D30="Sim",0.12,0.04) -> 0.04 | L30: 104.82927 | M30: =L30*1.23 -> 128.94 | N30: =L30*1.2 -> 125.79512 | O30: =L30*1.17 -> 122.65024 | P30: =(O30+L30)/2 -> 113.73976 | Q30: =L30*1.01249086924762 -> 106.13868 | S30: PDV | T30: #N/A | U30: #N/A | V30: #N/A | W30: #N/A | X30: #N/A | Y30: #N/A
B31: Windows 11 PRO COEM (FQC-10520) (I3 - I5) | C31: #N/A | G31: =IF(D31="Sim",0.12,0.04) -> 0.04 | L31: 123.8374 | M31: =L31*1.23 -> 152.32 | N31: =L31*1.2 -> 148.60488 | O31: =L31*1.17 -> 144.88976 | P31: =(O31+L31)/2 -> 134.36358 | Q31: =L31*1.01249086924762 -> 125.38424 | S31: PDV | T31: #N/A | U31: #N/A | V31: #N/A | W31: #N/A | X31: #N/A | Y31: #N/A
A32: 911MX010400733 | B32: IMP TERM P3L 80MM USB ETH RS232 BRA | C32: 8443.32.99 | D32: Não | E32: 3 anos | F32: 0.15 | G32: =IF(D32="Sim",0.12,0.04) -> 0.04 | L32: 67.504065 | M32: =L32*1.23 -> 83.03 | N32: =L32*1.2 -> 81.004878 | O32: =L32*1.17 -> 78.979756 | P32: =(O32+L32)/2 -> 73.241911 | Q32: =L32*1.01249086924762 -> 68.347249 | S32: IMPRESSORA DESKTOP | T32: N/A | U32: N/A | V32: N/A | W32: N/A | X32: N/A | Y32: N/A
A33: 911MK010200233 | B33: IMP TERM ETQ D4 102 PRETA USB BRA | C33: 8443.32.99 | D33: Não | E33: 1 ano | F33: 0.15 | G33: =IF(D33="Sim",0.12,0.04) -> 0.04 | L33: 171.10334 | M33: =L33*1.23 -> 210.4571 | N33: =L33*1.2 -> 205.324 | O33: =L33*1.17 -> 200.1909 | P33: =(O33+L33)/2 -> 185.64712 | Q33: =L33*1.01249086924762 -> 173.24057 | S33: IMPRESSORA DESKTOP | T33: N/A | U33: N/A | V33: N/A | W33: N/A | X33: N/A | Y33: N/A
A34: 911LB640200J33 | B34: IMP TERM DE ETQ CB425-LP USB+ETH | C34: 8443.32.99 | D34: Não | E34: 1 ano | F34: 0.15 | G34: =IF(D34="Sim",0.12,0.04) -> 0.04 | L34: 151.64175 | M34: =L34*1.23 -> 186.51935 | N34: =L34*1.2 -> 181.9701 | O34: =L34*1.17 -> 177.42085 | P34: =(O34+L34)/2 -> 164.5313 | Q34: =L34*1.01249086924762 -> 153.53589 | S34: IMPRESSORA DESKTOP | T34: N/A | U34: N/A | V34: N/A | W34: N/A | X34: N/A | Y34: N/A
A35: 995ED040700333 | B35: LEITOR CODIGO BARRAS 2D SR500NM USB STND | C35: 8471.90.12 | D35: Não | E35: 3 anos | F35: 0.0975 | G35: =IF(D35="Sim",0.12,0.04) -> 0.04 | L35: 136.95427 | M35: =L35*1.23 -> 168.45375 | N35: =L35*1.2 -> 164.34512 | O35: =L35*1.17 -> 160.23649 | P35: =(O35+L35)/2 -> 148.59538 | Q35: =L35*1.01249086924762 -> 138.66494 | S35: LEITOR DESKTOP | T35: N/A | U35: N/A | V35: N/A | W35: N/A | X35: N/A | Y35: N/A
A36: 995ED040800333 | B36: LEITOR CODIGO BARRAS 2D SM600U USB BRA | C36: 8471.90.12 | D36: Não | E36: 3 anos | F36: 0.0975 | G36: =IF(D36="Sim",0.12,0.04) -> 0.04 | L36: 67.901695 | M36: =L36*1.23 -> 83.519085 | N36: =L36*1.2 -> 81.482034 | O36: =L36*1.17 -> 79.444983 | P36: =(O36+L36)/2 -> 73.673339 | Q36: =L36*1.01249086924762 -> 68.749846 | S36: LEITOR DESKTOP | T36: N/A | U36: N/A | V36: N/A | W36: N/A | X36: N/A | Y36: N/A
A37: 992ED040700233 | B37: LEITOR DE CODIGO DE BARRAS CBR2D-V USB | C37: 8471.90.12 | D37: Não | E37: 3 anos | F37: 0.0975 | G37: =IF(D37="Sim",0.12,0.04) -> 0.04 | L37: 119.06505 | M37: =L37*1.23 -> 146.45001 | N37: =L37*1.2 -> 142.87806 | O37: =L37*1.17 -> 139.3061 | P37: =(O37+L37)/2 -> 129.18558 | Q37: =L37*1.01249086924762 -> 120.55227 | S37: LEITOR DESKTOP | T37: N/A | U37: N/A | V37: N/A | W37: N/A | X37: N/A | Y37: N/A
A38: 995ED049900300 | B38: LEITOR DE CODIGO DE BARRAS CBR2D-V USB/SERIAL | C38: 8471.90.12 | D38: Não | E38: 3 anos | F38: 0.0975 | G38: =IF(D38="Sim",0.12,0.04) -> 0.04 | L38: 132.07762 | M38: =L38*1.23 -> 162.45547 | N38: =L38*1.2 -> 158.49314 | O38: =L38*1.17 -> 154.53082 | P38: =(O38+L38)/2 -> 143.30422 | Q38: =L38*1.01249086924762 -> 133.72738 | S38: LEITOR DESKTOP | T38: N/A | U38: N/A | V38: N/A | W38: N/A | X38: N/A | Y38: N/A
A39: 992ED040500233 | B39: LEITOR DE CODIGO DE BARRAS CBR2D-P COM PEDESTAL USB | C39: 8471.90.12 | D39: Não | E39: 3 anos | F39: 0.0975 | G39: =IF(D39="Sim",0.12,0.04) -> 0.04 | L39: 47.758913 | M39: =L39*1.23 -> 58.743463 | N39: =L39*1.2 -> 57.310696 | O39: =L39*1.17 -> 55.877928 | P39: =(O39+L39)/2 -> 51.818421 | Q39: =L39*1.01249086924762 -> 48.355463 | S39: LEITOR DESKTOP | T39: N/A | U39: N/A | V39: N/A | W39: N/A | X39: N/A | Y39: N/A
A40: 915DX012000300 | B40: VKP80III IMPRESSORA TERMICA RX65 USB RS232 REAR+HOLDER+ACES BRA(NOVA) | C40: 8443.32.99 | D40: Sim | E40: 1 ano | F40: 0.15 | G40: =IF(D40="Sim",0.12,0.04) -> 0.12 | L40: 276.28738 | M40: =L40*1.23 -> 339.83348 | N40: =L40*1.2 -> 331.54485 | O40: =L40*1.17 -> 323.25623 | P40: =(O40+L40)/2 -> 299.77181 | Q40: =L40*1.01249086924762 -> 279.73845 | S40: IMPRESSORA OPEN FRAME | T40: N/A | U40: N/A | V40: N/A | W40: N/A | X40: N/A | Y40: N/A
...

Sheet 2026
A1: PN | B1: DESCRIÇÃO | C1: NCM | D1: PPB | E1: GARANTIA | F1: IPI | G1: ICMS | H1: ESTADO DESTINO | I1: NATUREZA OPERAÇÃO | J1: IE? | K1: IMPOSTO | L1: DISTRI | M1: 1 - 5 | N1: 6 - 10 | O1: 10+ | P1: ESPECIAL | Q1: SHOWROOM | R1: Tem na 2025? | S1: Categoria | T1: Processador | U1: Tela Principal | V1: Tela Secundária | W1: Touch 2a Tela | X1: RAM | Y1: SSD
A2: 932AD150300M33 | B2: MON LCD LITE 10.1 VGA/HDMI LOGO CBR BRA | C2: 8528.52.00 | D2: Não | E2: 1 ano | F2: 0.15 | G2: =IF(Table1[[#This Row],[PPB]]="Sim",0.12,0.04) -> 0.04 | K2: {=IF(AND(Table1[[#This Row],[NATUREZA OPERAÇÃO]]="REVENDA",Table1[[#This Row],[IE?]]="SIM"),INDEX(IMPOSTOS!E:E,MATCH(1,(IMPOSTOS!B:B=Table1[[#This Row],[NCM]])*(IMPOSTOS!C:C=Table1[[#This Row],[ESTADO DESTINO]])*(IMPOSTOS!D:D=Table1[[#This Row],[ICMS]]),0)),IF(AND(Table1[[#This Row],[NATUREZA OPERAÇÃO]]="CONSUMO",Table1[[#This Row],[IE?]]="SIM"),INDEX(IMPOSTOS!F:F,MATCH(1,(IMPOSTOS!B:B=Table1[[#This Row],[NCM]])*(IMPOSTOS!C:C=Table1[[#This Row],[ESTADO DESTINO]])*(IMPOSTOS!D:D=Table1[[#This Row],[ICMS]]),0)),IF(AND(Table1[[#This Row],[NATUREZA OPERAÇÃO]]="CONSUMO",Table1[[#This Row],[IE?]]="NÃO"),INDEX(IMPOSTOS!G:G,MATCH(1,(IMPOSTOS!B:B=Table1[[#This Row],[NCM]])*(IMPOSTOS!C:C=Table1[[#This Row],[ESTADO DESTINO]])*(IMPOSTOS!D:D=Table1[[#This Row],[ICMS]]),0)),"NÃO ENCONTRADO")))} -> NÃO ENCONTRADO | L2: 133.21354 | M2: =L2*1.23 -> 163.85266 | N2: =L2*1.2 -> 159.85625 | O2: =L2*1.17 -> 155.85985 | P2: =(L2+O2)/2 -> 144.5367 | Q2: =L2*1.01249086924762 -> 134.8775 | R2: =IFERROR(_xlfn.XLOOKUP(A2,'2025 NOV'!A:A,'2025 NOV'!L:L),"NÃO TEM NA LISTA 2025") -> NÃO TEM NA LISTA 2025 | S2: MONITOR LITE | T2: N/A | U2: 10.1 | V2: N/A | W2: N/A | X2: N/A | Y2: N/A
A3: 932AD150700M33 | B3: MON LCD PCAP LITE 10.1 VGA/HDMI LOGO CBR BRA | C3: 8528.52.00 | D3: Não | E3: 1 ano | F3: 0.15 | G3: =IF(Table1[[#This Row],[PPB]]="Sim",0.12,0.04) -> 0.04 | K3: {=IF(AND(Table1[[#This Row],[NATUREZA OPERAÇÃO]]="REVENDA",Table1[[#This Row],[IE?]]="SIM"),INDEX(IMPOSTOS!E:E,MATCH(1,(IMPOSTOS!B:B=Table1[[#This Row],[NCM]])*(IMPOSTOS!C:C=Table1[[#This Row],[ESTADO DESTINO]])*(IMPOSTOS!D:D=Table1[[#This Row],[ICMS]]),0)),IF(AND(Table1[[#This Row],[NATUREZA OPERAÇÃO]]="CONSUMO",Table1[[#This Row],[IE?]]="SIM"),INDEX(IMPOSTOS!F:F,MATCH(1,(IMPOSTOS!B:B=Table1[[#This Row],[NCM]])*(IMPOSTOS!C:C=Table1[[#This Row],[ESTADO DESTINO]])*(IMPOSTOS!D:D=Table1[[#This Row],[ICMS]]),0)),IF(AND(Table1[[#This Row],[NATUREZA OPERAÇÃO]]="CONSUMO",Table1[[#This Row],[IE?]]="NÃO"),INDEX(IMPOSTOS!G:G,MATCH(1,(IMPOSTOS!B:B=Table1[[#This Row],[NCM]])*(IMPOSTOS!C:C=Table1[[#This Row],[ESTADO DESTINO]])*(IMPOSTOS!D:D=Table1[[#This Row],[ICMS]]),0)),"NÃO ENCONTRADO")))} -> NÃO ENCONTRADO | L3: 159.38049 | M3: =L3*1.23 -> 196.038 | N3: =L3*1.2 -> 191.25659 | O3: =L3*1.17 -> 186.47517 | P3: =(L3+O3)/2 -> 172.92783 | Q3: =L3*1.01249086924762 -> 161.37129 | R3: =IFERROR(_xlfn.XLOOKUP(A3,'2025 NOV'!A:A,'2025 NOV'!L:L),"NÃO TEM NA LISTA 2025") -> NÃO TEM NA LISTA 2025 | S3: MONITOR LITE | T3: N/A | U3: 10.1 | V3: N/A | W3: N/A | X3: N/A | Y3: N/A
A4: 932AD161100M33 | B4: MON LCD PCAP LITE 15.6 VGA/HDMI LOGO CBR BRA | C4: 8528.52.00 | D4: Não | E4: 1 ano | F4: 0.15 | G4: =IF(Table1[[#This Row],[PPB]]="Sim",0.12,0.04) -> 0.04 | K4: {=IF(AND(Table1[[#This Row],[NATUREZA OPERAÇÃO]]="REVENDA",Table1[[#This Row],[IE?]]="SIM"),INDEX(IMPOSTOS!E:E,MATCH(1,(IMPOSTOS!B:B=Table1[[#This Row],[NCM]])*(IMPOSTOS!C:C=Table1[[#This Row],[ESTADO DESTINO]])*(IMPOSTOS!D:D=Table1[[#This Row],[ICMS]]),0)),IF(AND(Table1[[#This Row],[NATUREZA OPERAÇÃO]]="CONSUMO",Table1[[#This Row],[IE?]]="SIM"),INDEX(IMPOSTOS!F:F,MATCH(1,(IMPOSTOS!B:B=Table1[[#This Row],[NCM]])*(IMPOSTOS!C:C=Table1[[#This Row],[ESTADO DESTINO]])*(IMPOSTOS!D:D=Table1[[#This Row],[ICMS]]),0)),IF(AND(Table1[[#This Row],[NATUREZA OPERAÇÃO]]="CONSUMO",Table1[[#This Row],[IE?]]="NÃO"),INDEX(IMPOSTOS!G:G,MATCH(1,(IMPOSTOS!B:B=Table1[[#This Row],[NCM]])*(IMPOSTOS!C:C=Table1[[#This Row],[ESTADO DESTINO]])*(IMPOSTOS!D:D=Table1[[#This Row],[ICMS]]),0)),"NÃO ENCONTRADO")))} -> NÃO ENCONTRADO | L4: 259.94688 | M4: =L4*1.23 -> 319.73466 | N4: =L4*1.2 -> 311.93625 | O4: =L4*1.17 -> 304.13785 | P4: =(L4+O4)/2 -> 282.04236 | Q4: =L4*1.01249086924762 -> 263.19384 | R4: =IFERROR(_xlfn.XLOOKUP(A4,'2025 NOV'!A:A,'2025 NOV'!L:L),"NÃO TEM NA LISTA 2025") -> 250.78785 | S4: MONITOR LITE | T4: N/A | U4: 15.6 | V4: N/A | W4: N/A | X4: N/A | Y4: N/A
A5: 921LD020700733 | B5: NPDV FUSION PC 10.1 CX REG 2TPCAP IMP ETH PR DISP.CLI BRA * | C5: 8470.50.10 | D5: Não | E5: 3 anos | F5: 0.15 | G5: =IF(Table1[[#This Row],[PPB]]="Sim",0.12,0.04) -> 0.04 | K5: {=IF(AND(Table1[[#This Row],[NATUREZA OPERAÇÃO]]="REVENDA",Table1[[#This Row],[IE?]]="SIM"),INDEX(IMPOSTOS!E:E,MATCH(1,(IMPOSTOS!B:B=Table1[[#This Row],[NCM]])*(IMPOSTOS!C:C=Table1[[#This Row],[ESTADO DESTINO]])*(IMPOSTOS!D:D=Table1[[#This Row],[ICMS]]),0)),IF(AND(Table1[[#This Row],[NATUREZA OPERAÇÃO]]="CONSUMO",Table1[[#This Row],[IE?]]="SIM"),INDEX(IMPOSTOS!F:F,MATCH(1,(IMPOSTOS!B:B=Table1[[#This Row],[NCM]])*(IMPOSTOS!C:C=Table1[[#This Row],[ESTADO DESTINO]])*(IMPOSTOS!D:D=Table1[[#This Row],[ICMS]]),0)),IF(AND(Table1[[#This Row],[NATUREZA OPERAÇÃO]]="CONSUMO",Table1[[#This Row],[IE?]]="NÃO"),INDEX(IMPOSTOS!G:G,MATCH(1,(IMPOSTOS!B:B=Table1[[#This Row],[NCM]])*(IMPOSTOS!C:C=Table1[[#This Row],[ESTADO DESTINO]])*(IMPOSTOS!D:D=Table1[[#This Row],[ICMS]]),0)),"NÃO ENCONTRADO")))} -> NÃO ENCONTRADO | L5: 595.33779 | M5: =L5*1.23 -> 732.26548 | N5: =L5*1.2 -> 714.40535 | O5: =L5*1.17 -> 696.54521 | P5: =(L5+O5)/2 -> 645.9415 | Q5: =L5*1.01249086924762 -> 602.77407 | R5: =IFERROR(_xlfn.XLOOKUP(A5,'2025 NOV'!A:A,'2025 NOV'!L:L),"NÃO TEM NA LISTA 2025") -> 602.77407 | S5: PDV | T5: N3060 | U5: 10.1 | V5: N/A | W5: N/A | X5: 4 | Y5: 64
A6: 921LB660500733 | B6: CX REG SIRIUS 15.6 + 15.6 J6412 8/128 GB WIN IOT BRA | C6: 8470.50.10 | D6: Não | E6: 3 anos | F6: 0.15 | G6: =IF(Table1[[#This Row],[PPB]]="Sim",0.12,0.04) -> 0.04 | K6: {=IF(AND(Table1[[#This Row],[NATUREZA OPERAÇÃO]]="REVENDA",Table1[[#This Row],[IE?]]="SIM"),INDEX(IMPOSTOS!E:E,MATCH(1,(IMPOSTOS!B:B=Table1[[#This Row],[NCM]])*(IMPOSTOS!C:C=Table1[[#This Row],[ESTADO DESTINO]])*(IMPOSTOS!D:D=Table1[[#This Row],[ICMS]]),0)),IF(AND(Table1[[#This Row],[NATUREZA OPERAÇÃO]]="CONSUMO",Table1[[#This Row],[IE?]]="SIM"),INDEX(IMPOSTOS!F:F,MATCH(1,(IMPOSTOS!B:B=Table1[[#This Row],[NCM]])*(IMPOSTOS!C:C=Table1[[#This Row],[ESTADO DESTINO]])*(IMPOSTOS!D:D=Table1[[#This Row],[ICMS]]),0)),IF(AND(Table1[[#This Row],[NATUREZA OPERAÇÃO]]="CONSUMO",Table1[[#This Row],[IE?]]="NÃO"),INDEX(IMPOSTOS!G:G,MATCH(1,(IMPOSTOS!B:B=Table1[[#This Row],[NCM]])*(IMPOSTOS!C:C=Table1[[#This Row],[ESTADO DESTINO]])*(IMPOSTOS!D:D=Table1[[#This Row],[ICMS]]),0)),"NÃO ENCONTRADO")))} -> NÃO ENCONTRADO | L6: 1002.4309 | M6: =L6*1.23 -> 1232.99 | N6: =L6*1.2 -> 1202.9171 | O6: =L6*1.17 -> 1172.8441 | P6: =(L6+O6)/2 -> 1087.6375 | Q6: =L6*1.01249086924762 -> 1014.9521 | R6: =IFERROR(_xlfn.XLOOKUP(A6,'2025 NOV'!A:A,'2025 NOV'!L:L),"NÃO TEM NA LISTA 2025") -> NÃO TEM NA LISTA 2025 | S6: PDV | T6: J6412 | U6: 15.6 | V6: 15.6 | W6: NÃO | X6: 8 | Y6: 128
A7: 921LB660700733 | B7: CX REG SIRIUS 15.6 + 15.6 PCAP J6412 8/128 GB WIN IOT BRA | C7: 8470.50.10 | D7: Não | E7: 3 anos | F7: 0.15 | G7: =IF(Table1[[#This Row],[PPB]]="Sim",0.12,0.04) -> 0.04 | K7: {=IF(AND(Table1[[#This Row],[NATUREZA OPERAÇÃO]]="REVENDA",Table1[[#This Row],[IE?]]="SIM"),INDEX(IMPOSTOS!E:E,MATCH(1,(IMPOSTOS!B:B=Table1[[#This Row],[NCM]])*(IMPOSTOS!C:C=Table1[[#This Row],[ESTADO DESTINO]])*(IMPOSTOS!D:D=Table1[[#This Row],[ICMS]]),0)),IF(AND(Table1[[#This Row],[NATUREZA OPERAÇÃO]]="CONSUMO",Table1[[#This Row],[IE?]]="SIM"),INDEX(IMPOSTOS!F:F,MATCH(1,(IMPOSTOS!B:B=Table1[[#This Row],[NCM]])*(IMPOSTOS!C:C=Table1[[#This Row],[ESTADO DESTINO]])*(IMPOSTOS!D:D=Table1[[#This Row],[ICMS]]),0)),IF(AND(Table1[[#This Row],[NATUREZA OPERAÇÃO]]="CONSUMO",Table1[[#This Row],[IE?]]="NÃO"),INDEX(IMPOSTOS!G:G,MATCH(1,(IMPOSTOS!B:B=Table1[[#This Row],[NCM]])*(IMPOSTOS!C:C=Table1[[#This Row],[ESTADO DESTINO]])*(IMPOSTOS!D:D=Table1[[#This Row],[ICMS]]),0)),"NÃO ENCONTRADO")))} -> NÃO ENCONTRADO | L7: 1014.9106 | M7: =L7*1.23 -> 1248.34 | N7: =L7*1.2 -> 1217.8927 | O7: =L7*1.17 -> 1187.4454 | P7: =(L7+O7)/2 -> 1101.178 | Q7: =L7*1.01249086924762 -> 1027.5877 | R7: =IFERROR(_xlfn.XLOOKUP(A7,'2025 NOV'!A:A,'2025 NOV'!L:L),"NÃO TEM NA LISTA 2025") -> NÃO TEM NA LISTA 2025 | S7: PDV | T7: J6412 | U7: 15.6 | V7: 15.6 | W7: SIM | X7: 8 | Y7: 128
A8: 931FL103300L33 | B8: CX REG SIRIUS PC 15.6" PCAP + 15.6" J6412 8/128GB | C8: 8470.50.10 | D8: Não | E8: 3 anos | F8: 0.15 | G8: =IF(Table1[[#This Row],[PPB]]="Sim",0.12,0.04) -> 0.04 | K8: {=IF(AND(Table1[[#This Row],[NATUREZA OPERAÇÃO]]="REVENDA",Table1[[#This Row],[IE?]]="SIM"),INDEX(IMPOSTOS!E:E,MATCH(1,(IMPOSTOS!B:B=Table1[[#This Row],[NCM]])*(IMPOSTOS!C:C=Table1[[#This Row],[ESTADO DESTINO]])*(IMPOSTOS!D:D=Table1[[#This Row],[ICMS]]),0)),IF(AND(Table1[[#This Row],[NATUREZA OPERAÇÃO]]="CONSUMO",Table1[[#This Row],[IE?]]="SIM"),INDEX(IMPOSTOS!F:F,MATCH(1,(IMPOSTOS!B:B=Table1[[#This Row],[NCM]])*(IMPOSTOS!C:C=Table1[[#This Row],[ESTADO DESTINO]])*(IMPOSTOS!D:D=Table1[[#This Row],[ICMS]]),0)),IF(AND(Table1[[#This Row],[NATUREZA OPERAÇÃO]]="CONSUMO",Table1[[#This Row],[IE?]]="NÃO"),INDEX(IMPOSTOS!G:G,MATCH(1,(IMPOSTOS!B:B=Table1[[#This Row],[NCM]])*(IMPOSTOS!C:C=Table1[[#This Row],[ESTADO DESTINO]])*(IMPOSTOS!D:D=Table1[[#This Row],[ICMS]]),0)),"NÃO ENCONTRADO")))} -> NÃO ENCONTRADO | L8: 894.54091 | M8: =L8*1.23 -> 1100.2853 | N8: =L8*1.2 -> 1073.4491 | O8: =L8*1.17 -> 1046.6129 | P8: =(L8+O8)/2 -> 970.57688 | Q8: =L8*1.01249086924762 -> 905.7145 | R8: =IFERROR(_xlfn.XLOOKUP(A8,'2025 NOV'!A:A,'2025 NOV'!L:L),"NÃO TEM NA LISTA 2025") -> NÃO TEM NA LISTA 2025 | S8: PDV | T8: J6412 | U8: 15.6 | V8: 15.6 | W8: NÃO | X8: 8 | Y8: 128
A9: 931FL104900L33 | B9: CX REG SIRIUS PC 15.6" J6412 8/128GB | C9: 8470.50.10 | D9: Não | E9: 3 anos | F9: 0.15 | G9: =IF(Table1[[#This Row],[PPB]]="Sim",0.12,0.04) -> 0.04 | K9: {=IF(AND(Table1[[#This Row],[NATUREZA OPERAÇÃO]]="REVENDA",Table1[[#This Row],[IE?]]="SIM"),INDEX(IMPOSTOS!E:E,MATCH(1,(IMPOSTOS!B:B=Table1[[#This Row],[NCM]])*(IMPOSTOS!C:C=Table1[[#This Row],[ESTADO DESTINO]])*(IMPOSTOS!D:D=Table1[[#This Row],[ICMS]]),0)),IF(AND(Table1[[#This Row],[NATUREZA OPERAÇÃO]]="CONSUMO",Table1[[#This Row],[IE?]]="SIM"),INDEX(IMPOSTOS!F:F,MATCH(1,(IMPOSTOS!B:B=Table1[[#This Row],[NCM]])*(IMPOSTOS!C:C=Table1[[#This Row],[ESTADO DESTINO]])*(IMPOSTOS!D:D=Table1[[#This Row],[ICMS]]),0)),IF(AND(Table1[[#This Row],[NATUREZA OPERAÇÃO]]="CONSUMO",Table1[[#This Row],[IE?]]="NÃO"),INDEX(IMPOSTOS!G:G,MATCH(1,(IMPOSTOS!B:B=Table1[[#This Row],[NCM]])*(IMPOSTOS!C:C=Table1[[#This Row],[ESTADO DESTINO]])*(IMPOSTOS!D:D=Table1[[#This Row],[ICMS]]),0)),"NÃO ENCONTRADO")))} -> NÃO ENCONTRADO | L9: 750.79312 | M9: =L9*1.23 -> 923.47554 | N9: =L9*1.2 -> 900.95175 | O9: =L9*1.17 -> 878.42795 | P9: =(L9+O9)/2 -> 814.61054 | Q9: =L9*1.01249086924762 -> 760.17118 | R9: =IFERROR(_xlfn.XLOOKUP(A9,'2025 NOV'!A:A,'2025 NOV'!L:L),"NÃO TEM NA LISTA 2025") -> 529.60955 | S9: PDV | T9: J6412 | U9: 15.6 | V9: N/A | W9: N/A | X9: 8 | Y9: 128
A10: 931FL104900L33 | B10: CX REG SIRIUS PC 15.6" J6412 8/128GB (limitado a 212 pç) | C10: 8470.50.10 | D10: Não | E10: 3 anos | F10: 0.15 | G10: =IF(Table1[[#This Row],[PPB]]="Sim",0.12,0.04) -> 0.04 | K10: {=IF(AND(Table1[[#This Row],[NATUREZA OPERAÇÃO]]="REVENDA",Table1[[#This Row],[IE?]]="SIM"),INDEX(IMPOSTOS!E:E,MATCH(1,(IMPOSTOS!B:B=Table1[[#This Row],[NCM]])*(IMPOSTOS!C:C=Table1[[#This Row],[ESTADO DESTINO]])*(IMPOSTOS!D:D=Table1[[#This Row],[ICMS]]),0)),IF(AND(Table1[[#This Row],[NATUREZA OPERAÇÃO]]="CONSUMO",Table1[[#This Row],[IE?]]="SIM"),INDEX(IMPOSTOS!F:F,MATCH(1,(IMPOSTOS!B:B=Table1[[#This Row],[NCM]])*(IMPOSTOS!C:C=Table1[[#This Row],[ESTADO DESTINO]])*(IMPOSTOS!D:D=Table1[[#This Row],[ICMS]]),0)),IF(AND(Table1[[#This Row],[NATUREZA OPERAÇÃO]]="CONSUMO",Table1[[#This Row],[IE?]]="NÃO"),INDEX(IMPOSTOS!G:G,MATCH(1,(IMPOSTOS!B:B=Table1[[#This Row],[NCM]])*(IMPOSTOS!C:C=Table1[[#This Row],[ESTADO DESTINO]])*(IMPOSTOS!D:D=Table1[[#This Row],[ICMS]]),0)),"NÃO ENCONTRADO")))} -> NÃO ENCONTRADO | L10: 611.64228 | M10: =L10*1.23 -> 752.32 | N10: =L10*1.2 -> 733.97073 | O10: =L10*1.17 -> 715.62146 | P10: =(L10+O10)/2 -> 663.63187 | Q10: =L10*1.01249086924762 -> 619.28222 | R10: =IFERROR(_xlfn.XLOOKUP(A10,'2025 NOV'!A:A,'2025 NOV'!L:L),"NÃO TEM NA LISTA 2025") -> 529.60955 | S10: PDV | T10: J6412 | U10: 15.6 | V10: N/A | W10: N/A | X10: 8 | Y10: 128
A11: 921LB660400733 | B11: CX REG SIRIUS 15.6" J6412 8+128 GB WIN IOT BRA | C11: 8470.50.10 | D11: Não | E11: 3 anos | F11: 0.15 | G11: =IF(Table1[[#This Row],[PPB]]="Sim",0.12,0.04) -> 0.04 | K11: {=IF(AND(Table1[[#This Row],[NATUREZA OPERAÇÃO]]="REVENDA",Table1[[#This Row],[IE?]]="SIM"),INDEX(IMPOSTOS!E:E,MATCH(1,(IMPOSTOS!B:B=Table1[[#This Row],[NCM]])*(IMPOSTOS!C:C=Table1[[#This Row],[ESTADO DESTINO]])*(IMPOSTOS!D:D=Table1[[#This Row],[ICMS]]),0)),IF(AND(Table1[[#This Row],[NATUREZA OPERAÇÃO]]="CONSUMO",Table1[[#This Row],[IE?]]="SIM"),INDEX(IMPOSTOS!F:F,MATCH(1,(IMPOSTOS!B:B=Table1[[#This Row],[NCM]])*(IMPOSTOS!C:C=Table1[[#This Row],[ESTADO DESTINO]])*(IMPOSTOS!D:D=Table1[[#This Row],[ICMS]]),0)),IF(AND(Table1[[#This Row],[NATUREZA OPERAÇÃO]]="CONSUMO",Table1[[#This Row],[IE?]]="NÃO"),INDEX(IMPOSTOS!G:G,MATCH(1,(IMPOSTOS!B:B=Table1[[#This Row],[NCM]])*(IMPOSTOS!C:C=Table1[[#This Row],[ESTADO DESTINO]])*(IMPOSTOS!D:D=Table1[[#This Row],[ICMS]]),0)),"NÃO ENCONTRADO")))} -> NÃO ENCONTRADO | L11: 858.71545 | M11: =L11*1.23 -> 1056.22 | N11: =L11*1.2 -> 1030.4585 | O11: =L11*1.17 -> 1004.6971 | P11: =(L11+O11)/2 -> 931.70626 | Q11: =L11*1.01249086924762 -> 869.44155 | R11: =IFERROR(_xlfn.XLOOKUP(A11,'2025 NOV'!A:A,'2025 NOV'!L:L),"NÃO TEM NA LISTA 2025") -> 663.13841 | S11: PDV | T11: J6412 | U11: 15.6 | V11: N/A | W11: N/A | X11: 8 | Y11: 128
A12: 931FL105000L33 | B12: CX REG SIRIUS PC 15.6" J6412 8/128GB +11.6" NO TOUCH | C12: 8470.50.10 | D12: Não | E12: 3 anos | F12: 0.15 | G12: =IF(Table1[[#This Row],[PPB]]="Sim",0.12,0.04) -> 0.04 | K12: {=IF(AND(Table1[[#This Row],[NATUREZA OPERAÇÃO]]="REVENDA",Table1[[#This Row],[IE?]]="SIM"),INDEX(IMPOSTOS!E:E,MATCH(1,(IMPOSTOS!B:B=Table1[[#This Row],[NCM]])*(IMPOSTOS!C:C=Table1[[#This Row],[ESTADO DESTINO]])*(IMPOSTOS!D:D=Table1[[#This Row],[ICMS]]),0)),IF(AND(Table1[[#This Row],[NATUREZA OPERAÇÃO]]="CONSUMO",Table1[[#This Row],[IE?]]="SIM"),INDEX(IMPOSTOS!F:F,MATCH(1,(IMPOSTOS!B:B=Table1[[#This Row],[NCM]])*(IMPOSTOS!C:C=Table1[[#This Row],[ESTADO DESTINO]])*(IMPOSTOS!D:D=Table1[[#This Row],[ICMS]]),0)),IF(AND(Table1[[#This Row],[NATUREZA OPERAÇÃO]]="CONSUMO",Table1[[#This Row],[IE?]]="NÃO"),INDEX(IMPOSTOS!G:G,MATCH(1,(IMPOSTOS!B:B=Table1[[#This Row],[NCM]])*(IMPOSTOS!C:C=Table1[[#This Row],[ESTADO DESTINO]])*(IMPOSTOS!D:D=Table1[[#This Row],[ICMS]]),0)),"NÃO ENCONTRADO")))} -> NÃO ENCONTRADO | L12: 847.30456 | M12: =L12*1.23 -> 1042.1846 | N12: =L12*1.2 -> 1016.7655 | O12: =L12*1.17 -> 991.34633 | P12: =(L12+O12)/2 -> 919.32544 | Q12: =L12*1.01249086924762 -> 857.88813 | R12: =IFERROR(_xlfn.XLOOKUP(A12,'2025 NOV'!A:A,'2025 NOV'!L:L),"NÃO TEM NA LISTA 2025") -> 678.29917 | S12: PDV | T12: J6412 | U12: 15.6 | V12: 11.6 | W12: NÃO | X12: 8 | Y12: 128
A13: 921LB660600733 | B13: CX REG SIRIUS 15.6" + 11.6" J6412 8+128 GB NO TOUCH WIN IOT BRA | C13: 8470.50.10 | D13: Não | E13: 3 anos | F13: 0.15 | G13: =IF(Table1[[#This Row],[PPB]]="Sim",0.12,0.04) -> 0.04 | K13: {=IF(AND(Table1[[#This Row],[NATUREZA OPERAÇÃO]]="REVENDA",Table1[[#This Row],[IE?]]="SIM"),INDEX(IMPOSTOS!E:E,MATCH(1,(IMPOSTOS!B:B=Table1[[#This Row],[NCM]])*(IMPOSTOS!C:C=Table1[[#This Row],[ESTADO DESTINO]])*(IMPOSTOS!D:D=Table1[[#This Row],[ICMS]]),0)),IF(AND(Table1[[#This Row],[NATUREZA OPERAÇÃO]]="CONSUMO",Table1[[#This Row],[IE?]]="SIM"),INDEX(IMPOSTOS!F:F,MATCH(1,(IMPOSTOS!B:B=Table1[[#This Row],[NCM]])*(IMPOSTOS!C:C=Table1[[#This Row],[ESTADO DESTINO]])*(IMPOSTOS!D:D=Table1[[#This Row],[ICMS]]),0)),IF(AND(Table1[[#This Row],[NATUREZA OPERAÇÃO]]="CONSUMO",Table1[[#This Row],[IE?]]="NÃO"),INDEX(IMPOSTOS!G:G,MATCH(1,(IMPOSTOS!B:B=Table1[[#This Row],[NCM]])*(IMPOSTOS!C:C=Table1[[#This Row],[ESTADO DESTINO]])*(IMPOSTOS!D:D=Table1[[#This Row],[ICMS]]),0)),"NÃO ENCONTRADO")))} -> NÃO ENCONTRADO | L13: 954.68293 | M13: =L13*1.23 -> 1174.26 | N13: =L13*1.2 -> 1145.6195 | O13: =L13*1.17 -> 1116.979 | P13: =(L13+O13)/2 -> 1035.831 | Q13: =L13*1.01249086924762 -> 966.60775 | R13: =IFERROR(_xlfn.XLOOKUP(A13,'2025 NOV'!A:A,'2025 NOV'!L:L),"NÃO TEM NA LISTA 2025") -> 794.53244 | S13: PDV | T13: J6412 | U13: 15.6 | V13: 11.6 | W13: NÃO | X13: 8 | Y13: 128
A14: 931FL105100L33 | B14: CX REG SIRIUS PC 15.6" J6412 8/128GB +11.6" TOUCH | C14: 8470.50.10 | D14: Não | E14: 3 anos | F14: 0.15 | G14: =IF(Table1[[#This Row],[PPB]]="Sim",0.12,0.04) -> 0.04 | K14: {=IF(AND(Table1[[#This Row],[NATUREZA OPERAÇÃO]]="REVENDA",Table1[[#This Row],[IE?]]="SIM"),INDEX(IMPOSTOS!E:E,MATCH(1,(IMPOSTOS!B:B=Table1[[#This Row],[NCM]])*(IMPOSTOS!C:C=Table1[[#This Row],[ESTADO DESTINO]])*(IMPOSTOS!D:D=Table1[[#This Row],[ICMS]]),0)),IF(AND(Table1[[#This Row],[NATUREZA OPERAÇÃO]]="CONSUMO",Table1[[#This Row],[IE?]]="SIM"),INDEX(IMPOSTOS!F:F,MATCH(1,(IMPOSTOS!B:B=Table1[[#This Row],[NCM]])*(IMPOSTOS!C:C=Table1[[#This Row],[ESTADO DESTINO]])*(IMPOSTOS!D:D=Table1[[#This Row],[ICMS]]),0)),IF(AND(Table1[[#This Row],[NATUREZA OPERAÇÃO]]="CONSUMO",Table1[[#This Row],[IE?]]="NÃO"),INDEX(IMPOSTOS!G:G,MATCH(1,(IMPOSTOS!B:B=Table1[[#This Row],[NCM]])*(IMPOSTOS!C:C=Table1[[#This Row],[ESTADO DESTINO]])*(IMPOSTOS!D:D=Table1[[#This Row],[ICMS]]),0)),"NÃO ENCONTRADO")))} -> NÃO ENCONTRADO | L14: 887.95624 | M14: =L14*1.23 -> 1092.1862 | N14: =L14*1.2 -> 1065.5475 | O14: =L14*1.17 -> 1038.9088 | P14: =(L14+O14)/2 -> 963.43252 | Q14: =L14*1.01249086924762 -> 899.04758 | R14: =IFERROR(_xlfn.XLOOKUP(A14,'2025 NOV'!A:A,'2025 NOV'!L:L),"NÃO TEM NA LISTA 2025") -> 716.16105 | S14: PDV | T14: J6412 | U14: 15.6 | V14: 11.6 | W14: SIM | X14: 8 | Y14: 128
A15: 931FL105200L33 | B15: CX REG SIRIUS PC 15.6" J6412 8/128GB +15.6" TOUCH | C15: 8470.50.10 | D15: Não | E15: 3 anos | F15: 0.15 | G15: =IF(Table1[[#This Row],[PPB]]="Sim",0.12,0.04) -> 0.04 | K15: {=IF(AND(Table1[[#This Row],[NATUREZA OPERAÇÃO]]="REVENDA",Table1[[#This Row],[IE?]]="SIM"),INDEX(IMPOSTOS!E:E,MATCH(1,(IMPOSTOS!B:B=Table1[[#This Row],[NCM]])*(IMPOSTOS!C:C=Table1[[#This Row],[ESTADO DESTINO]])*(IMPOSTOS!D:D=Table1[[#This Row],[ICMS]]),0)),IF(AND(Table1[[#This Row],[NATUREZA OPERAÇÃO]]="CONSUMO",Table1[[#This Row],[IE?]]="SIM"),INDEX(IMPOSTOS!F:F,MATCH(1,(IMPOSTOS!B:B=Table1[[#This Row],[NCM]])*(IMPOSTOS!C:C=Table1[[#This Row],[ESTADO DESTINO]])*(IMPOSTOS!D:D=Table1[[#This Row],[ICMS]]),0)),IF(AND(Table1[[#This Row],[NATUREZA OPERAÇÃO]]="CONSUMO",Table1[[#This Row],[IE?]]="NÃO"),INDEX(IMPOSTOS!G:G,MATCH(1,(IMPOSTOS!B:B=Table1[[#This Row],[NCM]])*(IMPOSTOS!C:C=Table1[[#This Row],[ESTADO DESTINO]])*(IMPOSTOS!D:D=Table1[[#This Row],[ICMS]]),0)),"NÃO ENCONTRADO")))} -> NÃO ENCONTRADO | L15: 906.47846 | M15: =L15*1.23 -> 1114.9685 | N15: =L15*1.2 -> 1087.7742 | O15: =L15*1.17 -> 1060.5798 | P15: =(L15+O15)/2 -> 983.52913 | Q15: =L15*1.01249086924762 -> 917.80117 | R15: =IFERROR(_xlfn.XLOOKUP(A15,'2025 NOV'!A:A,'2025 NOV'!L:L),"NÃO TEM NA LISTA 2025") -> NÃO TEM NA LISTA 2025 | S15: PDV | T15: J6412 | U15: 15.6 | V15: 15.6 | W15: SIM | X15: 8 | Y15: 128
A16: 921LB660800733 | B16: CX REG SIRIUS 15.6" + 11.6" PCAP J6412 8+128 GB TOUCH WIN IOT BRA | C16: 8470.50.10 | D16: Não | E16: 3 anos | F16: 0.15 | G16: =IF(Table1[[#This Row],[PPB]]="Sim",0.12,0.04) -> 0.04 | K16: {=IF(AND(Table1[[#This Row],[NATUREZA OPERAÇÃO]]="REVENDA",Table1[[#This Row],[IE?]]="SIM"),INDEX(IMPOSTOS!E:E,MATCH(1,(IMPOSTOS!B:B=Table1[[#This Row],[NCM]])*(IMPOSTOS!C:C=Table1[[#This Row],[ESTADO DESTINO]])*(IMPOSTOS!D:D=Table1[[#This Row],[ICMS]]),0)),IF(AND(Table1[[#This Row],[NATUREZA OPERAÇÃO]]="CONSUMO",Table1[[#This Row],[IE?]]="SIM"),INDEX(IMPOSTOS!F:F,MATCH(1,(IMPOSTOS!B:B=Table1[[#This Row],[NCM]])*(IMPOSTOS!C:C=Table1[[#This Row],[ESTADO DESTINO]])*(IMPOSTOS!D:D=Table1[[#This Row],[ICMS]]),0)),IF(AND(Table1[[#This Row],[NATUREZA OPERAÇÃO]]="CONSUMO",Table1[[#This Row],[IE?]]="NÃO"),INDEX(IMPOSTOS!G:G,MATCH(1,(IMPOSTOS!B:B=Table1[[#This Row],[NCM]])*(IMPOSTOS!C:C=Table1[[#This Row],[ESTADO DESTINO]])*(IMPOSTOS!D:D=Table1[[#This Row],[ICMS]]),0)),"NÃO ENCONTRADO")))} -> NÃO ENCONTRADO | L16: 995.81301 | M16: =L16*1.23 -> 1224.85 | N16: =L16*1.2 -> 1194.9756 | O16: =L16*1.17 -> 1165.1012 | P16: =(L16+O16)/2 -> 1080.4571 | Q16: =L16*1.01249086924762 -> 1008.2516 | R16: =IFERROR(_xlfn.XLOOKUP(A16,'2025 NOV'!A:A,'2025 NOV'!L:L),"NÃO TEM NA LISTA 2025") -> 833.11351 | S16: PDV | T16: J6412 | U16: 15.6 | V16: 11.6 | W16: SIM | X16: 8 | Y16: 128
A17: 931FL102900L33 | B17: CX REG VEGA 11.6 J6412 8+128 GB | C17: 8470.50.10 | D17: Não | E17: 3 anos | F17: 0.15 | G17: =IF(Table1[[#This Row],[PPB]]="Sim",0.12,0.04) -> 0.04 | K17: {=IF(AND(Table1[[#This Row],[NATUREZA OPERAÇÃO]]="REVENDA",Table1[[#This Row],[IE?]]="SIM"),INDEX(IMPOSTOS!E:E,MATCH(1,(IMPOSTOS!B:B=Table1[[#This Row],[NCM]])*(IMPOSTOS!C:C=Table1[[#This Row],[ESTADO DESTINO]])*(IMPOSTOS!D:D=Table1[[#This Row],[ICMS]]),0)),IF(AND(Table1[[#This Row],[NATUREZA OPERAÇÃO]]="CONSUMO",Table1[[#This Row],[IE?]]="SIM"),INDEX(IMPOSTOS!F:F,MATCH(1,(IMPOSTOS!B:B=Table1[[#This Row],[NCM]])*(IMPOSTOS!C:C=Table1[[#This Row],[ESTADO DESTINO]])*(IMPOSTOS!D:D=Table1[[#This Row],[ICMS]]),0)),IF(AND(Table1[[#This Row],[NATUREZA OPERAÇÃO]]="CONSUMO",Table1[[#This Row],[IE?]]="NÃO"),INDEX(IMPOSTOS!G:G,MATCH(1,(IMPOSTOS!B:B=Table1[[#This Row],[NCM]])*(IMPOSTOS!C:C=Table1[[#This Row],[ESTADO DESTINO]])*(IMPOSTOS!D:D=Table1[[#This Row],[ICMS]]),0)),"NÃO ENCONTRADO")))} -> NÃO ENCONTRADO | L17: 827.446 | M17: =L17*1.23 -> 1017.7586 | N17: =L17*1.2 -> 992.9352 | O17: =L17*1.17 -> 968.11182 | P17: =(L17+O17)/2 -> 897.77891 | Q17: =L17*1.01249086924762 -> 837.78152 | R17: =IFERROR(_xlfn.XLOOKUP(A17,'2025 NOV'!A:A,'2025 NOV'!L:L),"NÃO TEM NA LISTA 2025") -> 655.98582 | S17: PDV | T17: J6412 | U17: 15.6 | V17: N/A | W17: N/A | X17: 8 | Y17: 128
A18: 931FL106000L33 | B18: CX REG VEGA PC 11.6" J6412 4/128GB IMP TER 80MM + ALTO-FALANTE | C18: 8470.50.10 | D18: Não | E18: 3 anos | F18: 0.15 | G18: =IF(Table1[[#This Row],[PPB]]="Sim",0.12,0.04) -> 0.04 | K18: {=IF(AND(Table1[[#This Row],[NATUREZA OPERAÇÃO]]="REVENDA",Table1[[#This Row],[IE?]]="SIM"),INDEX(IMPOSTOS!E:E,MATCH(1,(IMPOSTOS!B:B=Table1[[#This Row],[NCM]])*(IMPOSTOS!C:C=Table1[[#This Row],[ESTADO DESTINO]])*(IMPOSTOS!D:D=Table1[[#This Row],[ICMS]]),0)),IF(AND(Table1[[#This Row],[NATUREZA OPERAÇÃO]]="CONSUMO",Table1[[#This Row],[IE?]]="SIM"),INDEX(IMPOSTOS!F:F,MATCH(1,(IMPOSTOS!B:B=Table1[[#This Row],[NCM]])*(IMPOSTOS!C:C=Table1[[#This Row],[ESTADO DESTINO]])*(IMPOSTOS!D:D=Table1[[#This Row],[ICMS]]),0)),IF(AND(Table1[[#This Row],[NATUREZA OPERAÇÃO]]="CONSUMO",Table1[[#This Row],[IE?]]="NÃO"),INDEX(IMPOSTOS!G:G,MATCH(1,(IMPOSTOS!B:B=Table1[[#This Row],[NCM]])*(IMPOSTOS!C:C=Table1[[#This Row],[ESTADO DESTINO]])*(IMPOSTOS!D:D=Table1[[#This Row],[ICMS]]),0)),"NÃO ENCONTRADO")))} -> NÃO ENCONTRADO | L18: 827.446 | M18: =L18*1.23 -> 1017.7586 | N18: =L18*1.2 -> 992.9352 | O18: =L18*1.17 -> 968.11182 | P18: =(L18+O18)/2 -> 897.77891 | Q18: =L18*1.01249086924762 -> 837.78152 | R18: =IFERROR(_xlfn.XLOOKUP(A18,'2025 NOV'!A:A,'2025 NOV'!L:L),"NÃO TEM NA LISTA 2025") -> 656.05658 | S18: PDV | T18: J6412 | U18: 15.6 | V18: N/A | W18: N/A | X18: 4 | Y18: 128
A19: 921LB660100733 | B19: CX REG VEGA 11.6 J6412 4+128 GB WIN IOT BRA | C19: 8470.50.10 | D19: Não | E19: 3 anos | F19: 0.15 | G19: =IF(Table1[[#This Row],[PPB]]="Sim",0.12,0.04) -> 0.04 | K19: {=IF(AND(Table1[[#This Row],[NATUREZA OPERAÇÃO]]="REVENDA",Table1[[#This Row],[IE?]]="SIM"),INDEX(IMPOSTOS!E:E,MATCH(1,(IMPOSTOS!B:B=Table1[[#This Row],[NCM]])*(IMPOSTOS!C:C=Table1[[#This Row],[ESTADO DESTINO]])*(IMPOSTOS!D:D=Table1[[#This Row],[ICMS]]),0)),IF(AND(Table1[[#This Row],[NATUREZA OPERAÇÃO]]="CONSUMO",Table1[[#This Row],[IE?]]="SIM"),INDEX(IMPOSTOS!F:F,MATCH(1,(IMPOSTOS!B:B=Table1[[#This Row],[NCM]])*(IMPOSTOS!C:C=Table1[[#This Row],[ESTADO DESTINO]])*(IMPOSTOS!D:D=Table1[[#This Row],[ICMS]]),0)),IF(AND(Table1[[#This Row],[NATUREZA OPERAÇÃO]]="CONSUMO",Table1[[#This Row],[IE?]]="NÃO"),INDEX(IMPOSTOS!G:G,MATCH(1,(IMPOSTOS!B:B=Table1[[#This Row],[NCM]])*(IMPOSTOS!C:C=Table1[[#This Row],[ESTADO DESTINO]])*(IMPOSTOS!D:D=Table1[[#This Row],[ICMS]]),0)),"NÃO ENCONTRADO")))} -> NÃO ENCONTRADO | L19: 934.65262 | M19: =L19*1.23 -> 1149.6227 | N19: =L19*1.2 -> 1121.5831 | O19: =L19*1.17 -> 1093.5436 | P19: =(L19+O19)/2 -> 1014.0981 | Q19: =L19*1.01249086924762 -> 946.32724 | R19: =IFERROR(_xlfn.XLOOKUP(A19,'2025 NOV'!A:A,'2025 NOV'!L:L),"NÃO TEM NA LISTA 2025") -> 854.03084 | S19: PDV | T19: J6412 | U19: 15.6 | V19: N/A | W19: N/A | X19: 4 | Y19: 128
A20: 921LB661800733 | B20: CX REG VEGA PC 11.6" J6412 8/128GB WIN PRO IMP TER 80MM | C20: 8470.50.10 | D20: Não | E20: 3 anos | F20: 0.15 | G20: =IF(Table1[[#This Row],[PPB]]="Sim",0.12,0.04) -> 0.04 | K20: {=IF(AND(Table1[[#This Row],[NATUREZA OPERAÇÃO]]="REVENDA",Table1[[#This Row],[IE?]]="SIM"),INDEX(IMPOSTOS!E:E,MATCH(1,(IMPOSTOS!B:B=Table1[[#This Row],[NCM]])*(IMPOSTOS!C:C=Table1[[#This Row],[ESTADO DESTINO]])*(IMPOSTOS!D:D=Table1[[#This Row],[ICMS]]),0)),IF(AND(Table1[[#This Row],[NATUREZA OPERAÇÃO]]="CONSUMO",Table1[[#This Row],[IE?]]="SIM"),INDEX(IMPOSTOS!F:F,MATCH(1,(IMPOSTOS!B:B=Table1[[#This Row],[NCM]])*(IMPOSTOS!C:C=Table1[[#This Row],[ESTADO DESTINO]])*(IMPOSTOS!D:D=Table1[[#This Row],[ICMS]]),0)),IF(AND(Table1[[#This Row],[NATUREZA OPERAÇÃO]]="CONSUMO",Table1[[#This Row],[IE?]]="NÃO"),INDEX(IMPOSTOS!G:G,MATCH(1,(IMPOSTOS!B:B=Table1[[#This Row],[NCM]])*(IMPOSTOS!C:C=Table1[[#This Row],[ESTADO DESTINO]])*(IMPOSTOS!D:D=Table1[[#This Row],[ICMS]]),0)),"NÃO ENCONTRADO")))} -> NÃO ENCONTRADO | L20: 953.66639 | M20: =L20*1.23 -> 1173.0097 | N20: =L20*1.2 -> 1144.3997 | O20: =L20*1.17 -> 1115.7897 | P20: =(L20+O20)/2 -> 1034.728 | Q20: =L20*1.01249086924762 -> 965.57851 | R20: =IFERROR(_xlfn.XLOOKUP(A20,'2025 NOV'!A:A,'2025 NOV'!L:L),"NÃO TEM NA LISTA 2025") -> NÃO TEM NA LISTA 2025 | S20: PDV | T20: J6412 | U20: 15.6 | V20: N/A | W20: N/A | X20: 8 | Y20: 128
A21: 931FL103000L33 | B21: CX REG ANTARES PC 15.6"+11.6" J6412 4/128GB IMP TER 80MM | C21: 8470.50.10 | D21: Não | E21: 3 anos | F21: 0.15 | G21: =IF(Table1[[#This Row],[PPB]]="Sim",0.12,0.04) -> 0.04 | K21: {=IF(AND(Table1[[#This Row],[NATUREZA OPERAÇÃO]]="REVENDA",Table1[[#This Row],[IE?]]="SIM"),INDEX(IMPOSTOS!E:E,MATCH(1,(IMPOSTOS!B:B=Table1[[#This Row],[NCM]])*(IMPOSTOS!C:C=Table1[[#This Row],[ESTADO DESTINO]])*(IMPOSTOS!D:D=Table1[[#This Row],[ICMS]]),0)),IF(AND(Table1[[#This Row],[NATUREZA OPERAÇÃO]]="CONSUMO",Table1[[#This Row],[IE?]]="SIM"),INDEX(IMPOSTOS!F:F,MATCH(1,(IMPOSTOS!B:B=Table1[[#This Row],[NCM]])*(IMPOSTOS!C:C=Table1[[#This Row],[ESTADO DESTINO]])*(IMPOSTOS!D:D=Table1[[#This Row],[ICMS]]),0)),IF(AND(Table1[[#This Row],[NATUREZA OPERAÇÃO]]="CONSUMO",Table1[[#This Row],[IE?]]="NÃO"),INDEX(IMPOSTOS!G:G,MATCH(1,(IMPOSTOS!B:B=Table1[[#This Row],[NCM]])*(IMPOSTOS!C:C=Table1[[#This Row],[ESTADO DESTINO]])*(IMPOSTOS!D:D=Table1[[#This Row],[ICMS]]),0)),"NÃO ENCONTRADO")))} -> NÃO ENCONTRADO | L21: 706.87405 | M21: =L21*1.23 -> 869.45508 | N21: =L21*1.2 -> 848.24886 | O21: =L21*1.17 -> 827.04264 | P21: =(L21+O21)/2 -> 766.95835 | Q21: =L21*1.01249086924762 -> 715.70352 | R21: =IFERROR(_xlfn.XLOOKUP(A21,'2025 NOV'!A:A,'2025 NOV'!L:L),"NÃO TEM NA LISTA 2025") -> 715.90263 | S21: PDV | T21: J6412 | U21: 15.6 | V21: 11.6 | W21: SIM | X21: 4 | Y21: 128
A22: 931FL103000L33 | B22: CX REG ANTARES PC 15.6"+11.6" J6412 8/128GB IMP TER 80MM | C22: 8470.50.10 | D22: Não | E22: 3 anos | F22: 0.15 | G22: =IF(Table1[[#This Row],[PPB]]="Sim",0.12,0.04) -> 0.04 | K22: {=IF(AND(Table1[[#This Row],[NATUREZA OPERAÇÃO]]="REVENDA",Table1[[#This Row],[IE?]]="SIM"),INDEX(IMPOSTOS!E:E,MATCH(1,(IMPOSTOS!B:B=Table1[[#This Row],[NCM]])*(IMPOSTOS!C:C=Table1[[#This Row],[ESTADO DESTINO]])*(IMPOSTOS!D:D=Table1[[#This Row],[ICMS]]),0)),IF(AND(Table1[[#This Row],[NATUREZA OPERAÇÃO]]="CONSUMO",Table1[[#This Row],[IE?]]="SIM"),INDEX(IMPOSTOS!F:F,MATCH(1,(IMPOSTOS!B:B=Table1[[#This Row],[NCM]])*(IMPOSTOS!C:C=Table1[[#This Row],[ESTADO DESTINO]])*(IMPOSTOS!D:D=Table1[[#This Row],[ICMS]]),0)),IF(AND(Table1[[#This Row],[NATUREZA OPERAÇÃO]]="CONSUMO",Table1[[#This Row],[IE?]]="NÃO"),INDEX(IMPOSTOS!G:G,MATCH(1,(IMPOSTOS!B:B=Table1[[#This Row],[NCM]])*(IMPOSTOS!C:C=Table1[[#This Row],[ESTADO DESTINO]])*(IMPOSTOS!D:D=Table1[[#This Row],[ICMS]]),0)),"NÃO ENCONTRADO")))} -> NÃO ENCONTRADO | L22: 955.67064 | M22: =L22*1.23 -> 1175.4749 | N22: =L22*1.2 -> 1146.8048 | O22: =L22*1.17 -> 1118.1346 | P22: =(L22+O22)/2 -> 1036.9026 | Q22: =L22*1.01249086924762 -> 967.60779 | R22: =IFERROR(_xlfn.XLOOKUP(A22,'2025 NOV'!A:A,'2025 NOV'!L:L),"NÃO TEM NA LISTA 2025") -> 715.90263 | S22: PDV | T22: J6412 | U22: 15.6 | V22: 11.6 | W22: SIM | X22: 8 | Y22: 128
A23: 921LB660200733 | B23: CX REG ANTARES 15.6 J6412 4+128 GB WIN IOT BRA | C23: 8470.50.10 | D23: Não | E23: 3 anos | F23: 0.15 | G23: =IF(Table1[[#This Row],[PPB]]="Sim",0.12,0.04) -> 0.04 | K23: {=IF(AND(Table1[[#This Row],[NATUREZA OPERAÇÃO]]="REVENDA",Table1[[#This Row],[IE?]]="SIM"),INDEX(IMPOSTOS!E:E,MATCH(1,(IMPOSTOS!B:B=Table1[[#This Row],[NCM]])*(IMPOSTOS!C:C=Table1[[#This Row],[ESTADO DESTINO]])*(IMPOSTOS!D:D=Table1[[#This Row],[ICMS]]),0)),IF(AND(Table1[[#This Row],[NATUREZA OPERAÇÃO]]="CONSUMO",Table1[[#This Row],[IE?]]="SIM"),INDEX(IMPOSTOS!F:F,MATCH(1,(IMPOSTOS!B:B=Table1[[#This Row],[NCM]])*(IMPOSTOS!C:C=Table1[[#This Row],[ESTADO DESTINO]])*(IMPOSTOS!D:D=Table1[[#This Row],[ICMS]]),0)),IF(AND(Table1[[#This Row],[NATUREZA OPERAÇÃO]]="CONSUMO",Table1[[#This Row],[IE?]]="NÃO"),INDEX(IMPOSTOS!G:G,MATCH(1,(IMPOSTOS!B:B=Table1[[#This Row],[NCM]])*(IMPOSTOS!C:C=Table1[[#This Row],[ESTADO DESTINO]])*(IMPOSTOS!D:D=Table1[[#This Row],[ICMS]]),0)),"NÃO ENCONTRADO")))} -> NÃO ENCONTRADO | L23: 1067.4078 | M23: =L23*1.23 -> 1312.9116 | N23: =L23*1.2 -> 1280.8894 | O23: =L23*1.17 -> 1248.8672 | P23: =(L23+O23)/2 -> 1158.1375 | Q23: =L23*1.01249086924762 -> 1080.7407 | R23: =IFERROR(_xlfn.XLOOKUP(A23,'2025 NOV'!A:A,'2025 NOV'!L:L),"NÃO TEM NA LISTA 2025") -> 820.62894 | S23: PDV | T23: J6412 | U23: 15.6 | V23: 11.6 | W23: SIM | X23: 4 | Y23: 128
A24: 921LB661100733 | B24: CX REG SIRIUS PC 15.6" + 11.6" PCAP I3 10TH 8/128GB | C24: 8470.50.10 | D24: Não | E24: 3 anos | F24: 0.15 | G24: =IF(Table1[[#This Row],[PPB]]="Sim",0.12,0.04) -> 0.04 | K24: {=IF(AND(Table1[[#This Row],[NATUREZA OPERAÇÃO]]="REVENDA",Table1[[#This Row],[IE?]]="SIM"),INDEX(IMPOSTOS!E:E,MATCH(1,(IMPOSTOS!B:B=Table1[[#This Row],[NCM]])*(IMPOSTOS!C:C=Table1[[#This Row],[ESTADO DESTINO]])*(IMPOSTOS!D:D=Table1[[#This Row],[ICMS]]),0)),IF(AND(Table1[[#This Row],[NATUREZA OPERAÇÃO]]="CONSUMO",Table1[[#This Row],[IE?]]="SIM"),INDEX(IMPOSTOS!F:F,MATCH(1,(IMPOSTOS!B:B=Table1[[#This Row],[NCM]])*(IMPOSTOS!C:C=Table1[[#This Row],[ESTADO DESTINO]])*(IMPOSTOS!D:D=Table1[[#This Row],[ICMS]]),0)),IF(AND(Table1[[#This Row],[NATUREZA OPERAÇÃO]]="CONSUMO",Table1[[#This Row],[IE?]]="NÃO"),INDEX(IMPOSTOS!G:G,MATCH(1,(IMPOSTOS!B:B=Table1[[#This Row],[NCM]])*(IMPOSTOS!C:C=Table1[[#This Row],[ESTADO DESTINO]])*(IMPOSTOS!D:D=Table1[[#This Row],[ICMS]]),0)),"NÃO ENCONTRADO")))} -> NÃO ENCONTRADO | L24: 788.66242 | M24: =L24*1.23 -> 970.05477 | N24: =L24*1.2 -> 946.3949 | O24: =L24*1.17 -> 922.73503 | P24: =(L24+O24)/2 -> 855.69872 | Q24: =L24*1.01249086924762 -> 798.5135 | R24: =IFERROR(_xlfn.XLOOKUP(A24,'2025 NOV'!A:A,'2025 NOV'!L:L),"NÃO TEM NA LISTA 2025") -> 1013.765 | S24: PDV | T24: I3 | U24: 15.6 | V24: 11.6 | W24: SIM | X24: 8 | Y24: 128
